Workbook

Sheet InputOutput
A1: 1 | B1: 232
A2: 2 | B2: 1
A3: 3
A4: 4
A5: 5
A6: 6
A7: 7
A8: 8
A9: 9 | Q9: =DEC2HEX(MOD(SUMPRODUCT(B9:N9, TRANSPOSE({17;19;23;29;31;37;41;43;47;53;59;61;67})), 256), 2) -> 00
A10: 10
A11: 11
A12: 12
A13: 13
A14: 14
A15: 15
A16: 16
A17: 17
A18: 18 | B18: Alkutiedot | AG18: Tulokset | AY18: Lisätiedot
A19: 19 | BI19: ULS | BP19: SLS
A20: 20 | B20: Koko | C20: B | D20: HTVÄLI1 | E20: HTVÄLI2 | F20: HTKOKO | G20: HTPIT | H20: tyhjä | I20: tyhjä | J20: FCK | K20: ALPHACC | L20: TYHJÄ | M20: MYYS | N20: MYYC | O20: MYYP | P20: tyhjä | Q20: ID | BI20: Karki | BJ20: Joulukuusi | BK20: Joulukuusi.deg | BL20: Pohjalevy | BM20: Pohjalevy.deg | BN20: Betoni | BP20: Karki | BQ20: Joulukuusi | BR20: Joulukuusi.deg | BS20: Pohjalevy | BT20: Pohjalevy.deg | BU20: Betoni
A21: 21 | B21: 235 | C21: 232 | D21: 104 | E21: 0 | F21: 20 | G21: 660 | H21: 0 | I21: 0 | J21: 50 | K21: 1 | L21: 0 | M21: 1 | N21: 1 | O21: 1 | Q21: öö | BI21: =IF($AW21>=AG21,1,0) -> 1 | BJ21: =IF($AW21>=AH21,1,0) -> 1 | BK21: =IF($AW21>=AI21,1,0) -> 1 | BL21: =IF($AW21>=AJ21,1,0) -> 1 | BM21: =IF($AW21>=AK21,1,0) -> 1 | BN21: =IF($AW21>=AM21,1,0) -> 1 | BP21: =IF($AX21>=AO21,1,0) -> 1 | BQ21: =IF($AX21>=AP21,1,0) -> 1 | BR21: =IF($AX21>=AQ21,1,0) -> 1 | BS21: =IF($AX21>=AR21,1,0) -> 1 | BT21: =IF($AX21>=AS21,1,0) -> 1 | BU21: =IF($AX21>=AU21,1,0) -> 1
A22: 22 | B22: 235 | C22: 232 | D22: 104 | E22: 0 | F22: 20 | G22: 660 | H22: 0 | I22: 0 | J22: 50 | K22: 1 | L22: 0 | M22: 0.8 | N22: 0.8 | O22: 1 | Q22: öö | BI22: =IF($AW22>=AG22,1,0) -> 1 | BJ22: =IF($AW22>=AH22,1,0) -> 1 | BK22: =IF($AW22>=AI22,1,0) -> 1 | BL22: =IF($AW22>=AJ22,1,0) -> 1 | BM22: =IF($AW22>=AK22,1,0) -> 1 | BN22: =IF($AW22>=AM22,1,0) -> 1 | BP22: =IF($AX22>=AO22,1,0) -> 1 | BQ22: =IF($AX22>=AP22,1,0) -> 1 | BR22: =IF($AX22>=AQ22,1,0) -> 1 | BS22: =IF($AX22>=AR22,1,0) -> 1 | BT22: =IF($AX22>=AS22,1,0) -> 1 | BU22: =IF($AX22>=AU22,1,0) -> 1
A23: =A22+1 -> 23 | B23: 235 | C23: 232 | D23: 104 | E23: 0 | F23: 20 | G23: 660 | H23: 0 | I23: 0 | J23: 50 | K23: 1 | L23: 0 | M23: 0.9 | N23: 0.9 | O23: 1 | Q23: öö | BI23: =IF($AW23>=AG23,1,0) -> 1 | BJ23: =IF($AW23>=AH23,1,0) -> 1 | BK23: =IF($AW23>=AI23,1,0) -> 1 | BL23: =IF($AW23>=AJ23,1,0) -> 1 | BM23: =IF($AW23>=AK23,1,0) -> 1 | BN23: =IF($AW23>=AM23,1,0) -> 1 | BP23: =IF($AX23>=AO23,1,0) -> 1 | BQ23: =IF($AX23>=AP23,1,0) -> 1 | BR23: =IF($AX23>=AQ23,1,0) -> 1 | BS23: =IF($AX23>=AR23,1,0) -> 1 | BT23: =IF($AX23>=AS23,1,0) -> 1 | BU23: =IF($AX23>=AU23,1,0) -> 1
A24: =A23+1 -> 24 | B24: 270 | C24: 267 | D24: 104 | E24: 0 | F24: 20 | G24: 835 | H24: 0 | I24: 0 | J24: 50 | K24: 1 | L24: 0 | M24: 1 | N24: 1 | O24: 1 | Q24: öö | BI24: =IF($AW24>=AG24,1,0) -> 1 | BJ24: =IF($AW24>=AH24,1,0) -> 1 | BK24: =IF($AW24>=AI24,1,0) -> 1 | BL24: =IF($AW24>=AJ24,1,0) -> 1 | BM24: =IF($AW24>=AK24,1,0) -> 1 | BN24: =IF($AW24>=AM24,1,0) -> 1 | BP24: =IF($AX24>=AO24,1,0) -> 1 | BQ24: =IF($AX24>=AP24,1,0) -> 1 | BR24: =IF($AX24>=AQ24,1,0) -> 1 | BS24: =IF($AX24>=AR24,1,0) -> 1 | BT24: =IF($AX24>=AS24,1,0) -> 1 | BU24: =IF($AX24>=AU24,1,0) -> 1
A25: =A24+1 -> 25 | B25: 270 | C25: 267 | D25: 104 | E25: 0 | F25: 20 | G25: 835 | H25: 0 | I25: 0 | J25: 50 | K25: 1 | L25: 0 | M25: 0.8 | N25: 0.8 | O25: 1 | Q25: öö | BI25: =IF($AW25>=AG25,1,0) -> 1 | BJ25: =IF($AW25>=AH25,1,0) -> 1 | BK25: =IF($AW25>=AI25,1,0) -> 1 | BL25: =IF($AW25>=AJ25,1,0) -> 1 | BM25: =IF($AW25>=AK25,1,0) -> 1 | BN25: =IF($AW25>=AM25,1,0) -> 1 | BP25: =IF($AX25>=AO25,1,0) -> 1 | BQ25: =IF($AX25>=AP25,1,0) -> 1 | BR25: =IF($AX25>=AQ25,1,0) -> 1 | BS25: =IF($AX25>=AR25,1,0) -> 1 | BT25: =IF($AX25>=AS25,1,0) -> 1 | BU25: =IF($AX25>=AU25,1,0) -> 1
A26: =A25+1 -> 26 | B26: 270 | C26: 267 | D26: 104 | E26: 0 | F26: 20 | G26: 835 | H26: 0 | I26: 0 | J26: 50 | K26: 1 | L26: 0 | M26: 0.9 | N26: 0.9 | O26: 1 | Q26: öö | BI26: =IF($AW26>=AG26,1,0) -> 1 | BJ26: =IF($AW26>=AH26,1,0) -> 1 | BK26: =IF($AW26>=AI26,1,0) -> 1 | BL26: =IF($AW26>=AJ26,1,0) -> 1 | BM26: =IF($AW26>=AK26,1,0) -> 1 | BN26: =IF($AW26>=AM26,1,0) -> 1 | BP26: =IF($AX26>=AO26,1,0) -> 1 | BQ26: =IF($AX26>=AP26,1,0) -> 1 | BR26: =IF($AX26>=AQ26,1,0) -> 1 | BS26: =IF($AX26>=AR26,1,0) -> 1 | BT26: =IF($AX26>=AS26,1,0) -> 1 | BU26: =IF($AX26>=AU26,1,0) -> 1
A27: =A26+1 -> 27 | B27: 270 | C27: 267 | D27: 139 | E27: 0 | F27: 20 | G27: 835 | H27: 0 | I27: 0 | J27: 50 | K27: 1 | L27: 0 | M27: 1 | N27: 1 | O27: 1 | Q27: öö | BI27: =IF($AW27>=AG27,1,0) -> 1 | BJ27: =IF($AW27>=AH27,1,0) -> 1 | BK27: =IF($AW27>=AI27,1,0) -> 1 | BL27: =IF($AW27>=AJ27,1,0) -> 1 | BM27: =IF($AW27>=AK27,1,0) -> 1 | BN27: =IF($AW27>=AM27,1,0) -> 1 | BP27: =IF($AX27>=AO27,1,0) -> 1 | BQ27: =IF($AX27>=AP27,1,0) -> 1 | BR27: =IF($AX27>=AQ27,1,0) -> 1 | BS27: =IF($AX27>=AR27,1,0) -> 1 | BT27: =IF($AX27>=AS27,1,0) -> 1 | BU27: =IF($AX27>=AU27,1,0) -> 1
A28: =A27+1 -> 28 | B28: 270 | C28: 267 | D28: 139 | E28: 0 | F28: 20 | G28: 835 | H28: 0 | I28: 0 | J28: 50 | K28: 1 | L28: 0 | M28: 0.8 | N28: 0.8 | O28: 1 | Q28: öö | BI28: =IF($AW28>=AG28,1,0) -> 1 | BJ28: =IF($AW28>=AH28,1,0) -> 1 | BK28: =IF($AW28>=AI28,1,0) -> 1 | BL28: =IF($AW28>=AJ28,1,0) -> 1 | BM28: =IF($AW28>=AK28,1,0) -> 1 | BN28: =IF($AW28>=AM28,1,0) -> 1 | BP28: =IF($AX28>=AO28,1,0) -> 1 | BQ28: =IF($AX28>=AP28,1,0) -> 1 | BR28: =IF($AX28>=AQ28,1,0) -> 1 | BS28: =IF($AX28>=AR28,1,0) -> 1 | BT28: =IF($AX28>=AS28,1,0) -> 1 | BU28: =IF($AX28>=AU28,1,0) -> 1
A29: =A28+1 -> 29 | B29: 270 | C29: 267 | D29: 139 | E29: 0 | F29: 20 | G29: 835 | H29: 0 | I29: 0 | J29: 50 | K29: 1 | L29: 0 | M29: 0.9 | N29: 0.9 | O29: 1 | Q29: öö | BI29: =IF($AW29>=AG29,1,0) -> 1 | BJ29: =IF($AW29>=AH29,1,0) -> 1 | BK29: =IF($AW29>=AI29,1,0) -> 1 | BL29: =IF($AW29>=AJ29,1,0) -> 1 | BM29: =IF($AW29>=AK29,1,0) -> 1 | BN29: =IF($AW29>=AM29,1,0) -> 1 | BP29: =IF($AX29>=AO29,1,0) -> 1 | BQ29: =IF($AX29>=AP29,1,0) -> 1 | BR29: =IF($AX29>=AQ29,1,0) -> 1 | BS29: =IF($AX29>=AR29,1,0) -> 1 | BT29: =IF($AX29>=AS29,1,0) -> 1 | BU29: =IF($AX29>=AU29,1,0) -> 1
A30: =A29+1 -> 30 | B30: 235 | C30: 232 | D30: 104 | E30: 0 | F30: 20 | G30: 660 | H30: 0 | I30: 0 | J30: 60 | K30: 1 | L30: 0 | M30: 1 | N30: 1 | O30: 1 | Q30: öö | BI30: =IF($AW30>=AG30,1,0) -> 1 | BJ30: =IF($AW30>=AH30,1,0) -> 1 | BK30: =IF($AW30>=AI30,1,0) -> 1 | BL30: =IF($AW30>=AJ30,1,0) -> 1 | BM30: =IF($AW30>=AK30,1,0) -> 1 | BN30: =IF($AW30>=AM30,1,0) -> 1 | BP30: =IF($AX30>=AO30,1,0) -> 1 | BQ30: =IF($AX30>=AP30,1,0) -> 1 | BR30: =IF($AX30>=AQ30,1,0) -> 1 | BS30: =IF($AX30>=AR30,1,0) -> 1 | BT30: =IF($AX30>=AS30,1,0) -> 1 | BU30: =IF($AX30>=AU30,1,0) -> 1
A31: =A30+1 -> 31 | B31: 235 | C31: 232 | D31: 104 | E31: 0 | F31: 20 | G31: 660 | H31: 0 | I31: 0 | J31: 60 | K31: 1 | L31: 0 | M31: 0.8 | N31: 0.8 | O31: 1 | Q31: öö | BI31: =IF($AW31>=AG31,1,0) -> 1 | BJ31: =IF($AW31>=AH31,1,0) -> 1 | BK31: =IF($AW31>=AI31,1,0) -> 1 | BL31: =IF($AW31>=AJ31,1,0) -> 1 | BM31: =IF($AW31>=AK31,1,0) -> 1 | BN31: =IF($AW31>=AM31,1,0) -> 1 | BP31: =IF($AX31>=AO31,1,0) -> 1 | BQ31: =IF($AX31>=AP31,1,0) -> 1 | BR31: =IF($AX31>=AQ31,1,0) -> 1 | BS31: =IF($AX31>=AR31,1,0) -> 1 | BT31: =IF($AX31>=AS31,1,0) -> 1 | BU31: =IF($AX31>=AU31,1,0) -> 1
A32: =A31+1 -> 32 | B32: 235 | C32: 232 | D32: 104 | E32: 0 | F32: 20 | G32: 660 | H32: 0 | I32: 0 | J32: 60 | K32: 1 | L32: 0 | M32: 0.9 | N32: 0.9 | O32: 1 | Q32: öö | BI32: =IF($AW32>=AG32,1,0) -> 1 | BJ32: =IF($AW32>=AH32,1,0) -> 1 | BK32: =IF($AW32>=AI32,1,0) -> 1 | BL32: =IF($AW32>=AJ32,1,0) -> 1 | BM32: =IF($AW32>=AK32,1,0) -> 1 | BN32: =IF($AW32>=AM32,1,0) -> 1 | BP32: =IF($AX32>=AO32,1,0) -> 1 | BQ32: =IF($AX32>=AP32,1,0) -> 1 | BR32: =IF($AX32>=AQ32,1,0) -> 1 | BS32: =IF($AX32>=AR32,1,0) -> 1 | BT32: =IF($AX32>=AS32,1,0) -> 1 | BU32: =IF($AX32>=AU32,1,0) -> 1
A33: =A32+1 -> 33 | B33: 270 | C33: 267 | D33: 104 | E33: 0 | F33: 20 | G33: 835 | H33: 0 | I33: 0 | J33: 60 | K33: 1 | L33: 0 | M33: 1 | N33: 1 | O33: 1 | Q33: öö | BI33: =IF($AW33>=AG33,1,0) -> 1 | BJ33: =IF($AW33>=AH33,1,0) -> 1 | BK33: =IF($AW33>=AI33,1,0) -> 1 | BL33: =IF($AW33>=AJ33,1,0) -> 1 | BM33: =IF($AW33>=AK33,1,0) -> 1 | BN33: =IF($AW33>=AM33,1,0) -> 1 | BP33: =IF($AX33>=AO33,1,0) -> 1 | BQ33: =IF($AX33>=AP33,1,0) -> 1 | BR33: =IF($AX33>=AQ33,1,0) -> 1 | BS33: =IF($AX33>=AR33,1,0) -> 1 | BT33: =IF($AX33>=AS33,1,0) -> 1 | BU33: =IF($AX33>=AU33,1,0) -> 1
A34: =A33+1 -> 34 | B34: 270 | C34: 267 | D34: 104 | E34: 0 | F34: 20 | G34: 835 | H34: 0 | I34: 0 | J34: 60 | K34: 1 | L34: 0 | M34: 0.8 | N34: 0.8 | O34: 1 | Q34: öö | BI34: =IF($AW34>=AG34,1,0) -> 1 | BJ34: =IF($AW34>=AH34,1,0) -> 1 | BK34: =IF($AW34>=AI34,1,0) -> 1 | BL34: =IF($AW34>=AJ34,1,0) -> 1 | BM34: =IF($AW34>=AK34,1,0) -> 1 | BN34: =IF($AW34>=AM34,1,0) -> 1 | BP34: =IF($AX34>=AO34,1,0) -> 1 | BQ34: =IF($AX34>=AP34,1,0) -> 1 | BR34: =IF($AX34>=AQ34,1,0) -> 1 | BS34: =IF($AX34>=AR34,1,0) -> 1 | BT34: =IF($AX34>=AS34,1,0) -> 1 | BU34: =IF($AX34>=AU34,1,0) -> 1
... A38: =A37+1 -> 38 | B38: 270 | C38: 267 | D38: 139 | E38: 0 | F38: 20 | G38: 835 | H38: 0 | I38: 0 | J38: 60 | K38: 1 | L38: 0 | M38: 0.9 | N38: 0.9 | O38: 1 | Q38: öö | BI38: =IF($AW38>=AG38,1,0) -> 1 | BJ38: =IF($AW38>=AH38,1,0) -> 1 | BK38: =IF($AW38>=AI38,1,0) -> 1 | BL38: =IF($AW38>=AJ38,1,0) -> 1 | BM38: =IF($AW38>=AK38,1,0) -> 1 | BN38: =IF($AW38>=AM38,1,0) -> 1 | BP38: =IF($AX38>=AO38,1,0) -> 1 | BQ38: =IF($AX38>=AP38,1,0) -> 1 | BR38: =IF($AX38>=AQ38,1,0) -> 1 | BS38: =IF($AX38>=AR38,1,0) -> 1 | BT38: =IF($AX38>=AS38,1,0) -> 1 | BU38: =IF($AX38>=AU38,1,0) -> 1
A39: =A38+1 -> 39 | BI39: =IF($AW39>=AG39,1,0) -> 1 | BJ39: =IF($AW39>=AH39,1,0) -> 1 | BK39: =IF($AW39>=AI39,1,0) -> 1 | BL39: =IF($AW39>=AJ39,1,0) -> 1 | BM39: =IF($AW39>=AK39,1,0) -> 1 | BN39: =IF($AW39>=AM39,1,0) -> 1 | BP39: =IF($AX39>=AO39,1,0) -> 1 | BQ39: =IF($AX39>=AP39,1,0) -> 1 | BR39: =IF($AX39>=AQ39,1,0) -> 1 | BS39: =IF($AX39>=AR39,1,0) -> 1 | BT39: =IF($AX39>=AS39,1,0) -> 1 | BU39: =IF($AX39>=AU39,1,0) -> 1
A40: =A39+1 -> 40 | BI40: =IF($AW40>=AG40,1,0) -> 1 | BJ40: =IF($AW40>=AH40,1,0) -> 1 | BK40: =IF($AW40>=AI40,1,0) -> 1 | BL40: =IF($AW40>=AJ40,1,0) -> 1 | BM40: =IF($AW40>=AK40,1,0) -> 1 | BN40: =IF($AW40>=AM40,1,0) -> 1 | BP40: =IF($AX40>=AO40,1,0) -> 1 | BQ40: =IF($AX40>=AP40,1,0) -> 1 | BR40: =IF($AX40>=AQ40,1,0) -> 1 | BS40: =IF($AX40>=AR40,1,0) -> 1 | BT40: =IF($AX40>=AS40,1,0) -> 1 | BU40: =IF($AX40>=AU40,1,0) -> 1
A41: =A40+1 -> 41 | BI41: =IF($AW41>=AG41,1,0) -> 1 | BJ41: =IF($AW41>=AH41,1,0) -> 1 | BK41: =IF($AW41>=AI41,1,0) -> 1 | BL41: =IF($AW41>=AJ41,1,0) -> 1 | BM41: =IF($AW41>=AK41,1,0) -> 1 | BN41: =IF($AW41>=AM41,1,0) -> 1 | BP41: =IF($AX41>=AO41,1,0) -> 1 | BQ41: =IF($AX41>=AP41,1,0) -> 1 | BR41: =IF($AX41>=AQ41,1,0) -> 1 | BS41: =IF($AX41>=AR41,1,0) -> 1 | BT41: =IF($AX41>=AS41,1,0) -> 1 | BU41: =IF($AX41>=AU41,1,0) -> 1
A42: =A41+1 -> 42 | BI42: =IF($AW42>=AG42,1,0) -> 1 | BJ42: =IF($AW42>=AH42,1,0) -> 1 | BK42: =IF($AW42>=AI42,1,0) -> 1 | BL42: =IF($AW42>=AJ42,1,0) -> 1 | BM42: =IF($AW42>=AK42,1,0) -> 1 | BN42: =IF($AW42>=AM42,1,0) -> 1 | BP42: =IF($AX42>=AO42,1,0) -> 1 | BQ42: =IF($AX42>=AP42,1,0) -> 1 | BR42: =IF($AX42>=AQ42,1,0) -> 1 | BS42: =IF($AX42>=AR42,1,0) -> 1 | BT42: =IF($AX42>=AS42,1,0) -> 1 | BU42: =IF($AX42>=AU42,1,0) -> 1
A43: =A42+1 -> 43 | BI43: =IF($AW43>=AG43,1,0) -> 1 | BJ43: =IF($AW43>=AH43,1,0) -> 1 | BK43: =IF($AW43>=AI43,1,0) -> 1 | BL43: =IF($AW43>=AJ43,1,0) -> 1 | BM43: =IF($AW43>=AK43,1,0) -> 1 | BN43: =IF($AW43>=AM43,1,0) -> 1 | BP43: =IF($AX43>=AO43,1,0) -> 1 | BQ43: =IF($AX43>=AP43,1,0) -> 1 | BR43: =IF($AX43>=AQ43,1,0) -> 1 | BS43: =IF($AX43>=AR43,1,0) -> 1 | BT43: =IF($AX43>=AS43,1,0) -> 1 | BU43: =IF($AX43>=AU43,1,0) -> 1
...

Sheet tojson
A1: nro | B1: =IF(InputOutput!$B20="","",InputOutput!B20) -> Koko | C1: =IF(InputOutput!$B20="","",InputOutput!C20) -> B | D1: =IF(InputOutput!$B20="","",InputOutput!D20) -> HTVÄLI1 | E1: =IF(InputOutput!$B20="","",InputOutput!E20) -> HTVÄLI2 | F1: =IF(InputOutput!$B20="","",InputOutput!F20) -> HTKOKO | G1: =IF(InputOutput!$B20="","",InputOutput!G20) -> HTPIT | H1: =IF(InputOutput!$B20="","",InputOutput!H20) -> tyhjä | I1: =IF(InputOutput!$B20="","",InputOutput!I20) -> tyhjä | ... AD1: =IF(InputOutput!$B20="","",InputOutput!AD20) -> 0 | AE1: =IF(InputOutput!$B20="","",InputOutput!AW20) -> 0 | AF1: =IF(InputOutput!$B20="","",InputOutput!AX20) -> 0 | AG1: =IF(InputOutput!$B20="","",InputOutput!AY20) -> 0 | AH1: =IF(InputOutput!$B20="","",InputOutput!AZ20) -> 0 | AI1: =IF(InputOutput!$B20="","",InputOutput!BA20) -> 0 | AJ1: =IF(InputOutput!$B20="","",InputOutput!BB20) -> 0 | AK1: =IF(InputOutput!$B20="","",InputOutput!BC20) -> 0 | AL1: =IF(InputOutput!$B20="","",InputOutput!BD20) -> 0 | ... AN1: =IF(InputOutput!$B20="","",InputOutput!BF20) -> 0
A2: =IF(InputOutput!$B21="","",InputOutput!A21) -> 21 | B2: =IF(InputOutput!$B21="","",InputOutput!B21) -> 235 | C2: =IF(InputOutput!$B21="","",InputOutput!C21) -> 232 | D2: =IF(InputOutput!$B21="","",InputOutput!D21) -> 104 | E2: =IF(InputOutput!$B21="","",InputOutput!E21) -> 0 | F2: =IF(InputOutput!$B21="","",InputOutput!F21) -> 20 | G2: =IF(InputOutput!$B21="","",InputOutput!G21) -> 660 | H2: =IF(InputOutput!$B21="","",InputOutput!H21) -> 0 | ... AD2: =IF(InputOutput!$B21="","",InputOutput!AD21) -> 0 | AE2: =IF(InputOutput!$B21="","",ROUND(InputOutput!AW21,0)) -> 0 | AF2: =IF(InputOutput!$B21="","",ROUND(InputOutput!AX21,0)) -> 0 | AG2: =IF(InputOutput!$B21="","",InputOutput!AY21) -> 0 | AH2: =IF(InputOutput!$B21="","",InputOutput!AZ21) -> 0 | AI2: =IF(InputOutput!$B21="","",InputOutput!BA21) -> 0 | AJ2: =IF(InputOutput!$B21="","",InputOutput!BB21) -> 0 | AK2: =IF(InputOutput!$B21="","",InputOutput!BC21) -> 0 | AL2: =IF(InputOutput!$B21="","",InputOutput!BD21) -> 0 | AM2: =IF(InputOutput!$B21="","",InputOutput!BE21) -> 0 | AN2: =IF(InputOutput!$B21="","",InputOutput!BF21) -> 0
A3: =IF(InputOutput!$B22="","",InputOutput!A22) -> 22 | B3: =IF(InputOutput!$B22="","",InputOutput!B22) -> 235 | C3: =IF(InputOutput!$B22="","",InputOutput!C22) -> 232 | D3: =IF(InputOutput!$B22="","",InputOutput!D22) -> 104 | E3: =IF(InputOutput!$B22="","",InputOutput!E22) -> 0 | F3: =IF(InputOutput!$B22="","",InputOutput!F22) -> 20 | G3: =IF(InputOutput!$B22="","",InputOutput!G22) -> 660 | H3: =IF(InputOutput!$B22="","",InputOutput!H22) -> 0 | ... AD3: =IF(InputOutput!$B22="","",InputOutput!AD22) -> 0 | AE3: =IF(InputOutput!$B22="","",ROUND(InputOutput!AW22,0)) -> 0 | AF3: =IF(InputOutput!$B22="","",ROUND(InputOutput!AX22,0)) -> 0 | AG3: =IF(InputOutput!$B22="","",InputOutput!AY22) -> 0 | AH3: =IF(InputOutput!$B22="","",InputOutput!AZ22) -> 0 | AI3: =IF(InputOutput!$B22="","",InputOutput!BA22) -> 0 | AJ3: =IF(InputOutput!$B22="","",InputOutput!BB22) -> 0 | AK3: =IF(InputOutput!$B22="","",InputOutput!BC22) -> 0 | AL3: =IF(InputOutput!$B22="","",InputOutput!BD22) -> 0 | AM3: =IF(InputOutput!$B22="","",InputOutput!BE22) -> 0 | AN3: =IF(InputOutput!$B22="","",InputOutput!BF22) -> 0
A4: =IF(InputOutput!$B37="","",InputOutput!A23) -> 23 | B4: =IF(InputOutput!$B37="","",InputOutput!B37) -> 270 | C4: =IF(InputOutput!$B37="","",InputOutput!C37) -> 267 | D4: =IF(InputOutput!$B37="","",InputOutput!D37) -> 139 | E4: =IF(InputOutput!$B37="","",InputOutput!E37) -> 0 | F4: =IF(InputOutput!$B37="","",InputOutput!F37) -> 20 | G4: =IF(InputOutput!$B37="","",InputOutput!G37) -> 835 | H4: =IF(InputOutput!$B37="","",InputOutput!H37) -> 0 | I4: =IF(InputOutput!$B37="","",InputOutput!I37) -> 0 | ... Q4: =IF(InputOutput!$B37="","",InputOutput!Q37) -> öö | R4: =IF(InputOutput!$B37="","",InputOutput!R23) -> 0 | S4: =IF(InputOutput!$B37="","",InputOutput!S23) -> 0 | T4: =IF(InputOutput!$B37="","",InputOutput!T23) -> 0 | U4: =IF(InputOutput!$B37="","",InputOutput!U23) -> 0 | V4: =IF(InputOutput!$B37="","",InputOutput!V23) -> 0 | W4: =IF(InputOutput!$B37="","",InputOutput!W23) -> 0 | X4: =IF(InputOutput!$B37="","",InputOutput!X23) -> 0 | Y4: =IF(InputOutput!$B37="","",InputOutput!Y23) -> 0 | ... AD4: =IF(InputOutput!$B37="","",InputOutput!AD23) -> 0 | AE4: =IF(InputOutput!$B37="","",ROUND(InputOutput!AW23,0)) -> 0 | AF4: =IF(InputOutput!$B37="","",ROUND(InputOutput!AX23,0)) -> 0 | AG4: =IF(InputOutput!$B37="","",InputOutput!AY23) -> 0 | AH4: =IF(InputOutput!$B37="","",InputOutput!AZ23) -> 0 | AI4: =IF(InputOutput!$B37="","",InputOutput!BA23) -> 0 | AJ4: =IF(InputOutput!$B37="","",InputOutput!BB23) -> 0 | AK4: =IF(InputOutput!$B37="","",InputOutput!BC23) -> 0 | AL4: =IF(InputOutput!$B37="","",InputOutput!BD23) -> 0 | AM4: =IF(InputOutput!$B37="","",InputOutput!BE23) -> 0 | AN4: =IF(InputOutput!$B37="","",InputOutput!BF23) -> 0
A5: =IF(InputOutput!$B38="","",InputOutput!A24) -> 24 | B5: =IF(InputOutput!$B38="","",InputOutput!B38) -> 270 | C5: =IF(InputOutput!$B38="","",InputOutput!C38) -> 267 | D5: =IF(InputOutput!$B38="","",InputOutput!D38) -> 139 | E5: =IF(InputOutput!$B38="","",InputOutput!E38) -> 0 | F5: =IF(InputOutput!$B38="","",InputOutput!F38) -> 20 | G5: =IF(InputOutput!$B38="","",InputOutput!G38) -> 835 | H5: =IF(InputOutput!$B38="","",InputOutput!H38) -> 0 | I5: =IF(InputOutput!$B38="","",InputOutput!I38) -> 0 | ... Q5: =IF(InputOutput!$B38="","",InputOutput!Q38) -> öö | R5: =IF(InputOutput!$B38="","",InputOutput!R24) -> 0 | S5: =IF(InputOutput!$B38="","",InputOutput!S24) -> 0 | T5: =IF(InputOutput!$B38="","",InputOutput!T24) -> 0 | U5: =IF(InputOutput!$B38="","",InputOutput!U24) -> 0 | V5: =IF(InputOutput!$B38="","",InputOutput!V24) -> 0 | W5: =IF(InputOutput!$B38="","",InputOutput!W24) -> 0 | X5: =IF(InputOutput!$B38="","",InputOutput!X24) -> 0 | Y5: =IF(InputOutput!$B38="","",InputOutput!Y24) -> 0 | ... AD5: =IF(InputOutput!$B38="","",InputOutput!AD24) -> 0 | AE5: =IF(InputOutput!$B38="","",ROUND(InputOutput!AW24,0)) -> 0 | AF5: =IF(InputOutput!$B38="","",ROUND(InputOutput!AX24,0)) -> 0 | AG5: =IF(InputOutput!$B38="","",InputOutput!AY24) -> 0 | AH5: =IF(InputOutput!$B38="","",InputOutput!AZ24) -> 0 | AI5: =IF(InputOutput!$B38="","",InputOutput!BA24) -> 0 | AJ5: =IF(InputOutput!$B38="","",InputOutput!BB24) -> 0 | AK5: =IF(InputOutput!$B38="","",InputOutput!BC24) -> 0 | AL5: =IF(InputOutput!$B38="","",InputOutput!BD24) -> 0 | AM5: =IF(InputOutput!$B38="","",InputOutput!BE24) -> 0 | AN5: =IF(InputOutput!$B38="","",InputOutput!BF24) -> 0
A6: =IF(InputOutput!$B39="","",InputOutput!A25) | B6: =IF(InputOutput!$B39="","",InputOutput!B39) | C6: =IF(InputOutput!$B39="","",InputOutput!C39) | D6: =IF(InputOutput!$B39="","",InputOutput!D39) | E6: =IF(InputOutput!$B39="","",InputOutput!E39) | F6: =IF(InputOutput!$B39="","",InputOutput!F39) | G6: =IF(InputOutput!$B39="","",InputOutput!G39) | H6: =IF(InputOutput!$B39="","",InputOutput!H39) | I6: =IF(InputOutput!$B39="","",InputOutput!I39) | ... Q6: =IF(InputOutput!$B39="","",InputOutput!Q39) | R6: =IF(InputOutput!$B39="","",InputOutput!R25) | S6: =IF(InputOutput!$B39="","",InputOutput!S25) | T6: =IF(InputOutput!$B39="","",InputOutput!T25) | U6: =IF(InputOutput!$B39="","",InputOutput!U25) | V6: =IF(InputOutput!$B39="","",InputOutput!V25) | W6: =IF(InputOutput!$B39="","",InputOutput!W25) | X6: =IF(InputOutput!$B39="","",InputOutput!X25) | Y6: =IF(InputOutput!$B39="","",InputOutput!Y25) | ... AD6: =IF(InputOutput!$B39="","",InputOutput!AD25) | AE6: =IF(InputOutput!$B39="","",ROUND(InputOutput!AW25,0)) | AF6: =IF(InputOutput!$B39="","",ROUND(InputOutput!AX25,0)) | AG6: =IF(InputOutput!$B39="","",InputOutput!AY25) | AH6: =IF(InputOutput!$B39="","",InputOutput!AZ25) | AI6: =IF(InputOutput!$B39="","",InputOutput!BA25) | AJ6: =IF(InputOutput!$B39="","",InputOutput!BB25) | AK6: =IF(InputOutput!$B39="","",InputOutput!BC25) | AL6: =IF(InputOutput!$B39="","",InputOutput!BD25) | AM6: =IF(InputOutput!$B39="","",InputOutput!BE25) | AN6: =IF(InputOutput!$B39="","",InputOutput!BF25)
A7: =IF(InputOutput!$B40="","",InputOutput!A26) | B7: =IF(InputOutput!$B40="","",InputOutput!B40) | C7: =IF(InputOutput!$B40="","",InputOutput!C40) | D7: =IF(InputOutput!$B40="","",InputOutput!D40) | E7: =IF(InputOutput!$B40="","",InputOutput!E40) | F7: =IF(InputOutput!$B40="","",InputOutput!F40) | G7: =IF(InputOutput!$B40="","",InputOutput!G40) | H7: =IF(InputOutput!$B40="","",InputOutput!H40) | I7: =IF(InputOutput!$B40="","",InputOutput!I40) | ... Q7: =IF(InputOutput!$B40="","",InputOutput!Q40) | R7: =IF(InputOutput!$B40="","",InputOutput!R26) | S7: =IF(InputOutput!$B40="","",InputOutput!S26) | T7: =IF(InputOutput!$B40="","",InputOutput!T26) | U7: =IF(InputOutput!$B40="","",InputOutput!U26) | V7: =IF(InputOutput!$B40="","",InputOutput!V26) | W7: =IF(InputOutput!$B40="","",InputOutput!W26) | X7: =IF(InputOutput!$B40="","",InputOutput!X26) | Y7: =IF(InputOutput!$B40="","",InputOutput!Y26) | ... AD7: =IF(InputOutput!$B40="","",InputOutput!AD26) | AE7: =IF(InputOutput!$B40="","",ROUND(InputOutput!AW26,0)) | AF7: =IF(InputOutput!$B40="","",ROUND(InputOutput!AX26,0)) | AG7: =IF(InputOutput!$B40="","",InputOutput!AY26) | AH7: =IF(InputOutput!$B40="","",InputOutput!AZ26) | AI7: =IF(InputOutput!$B40="","",InputOutput!BA26) | AJ7: =IF(InputOutput!$B40="","",InputOutput!BB26) | AK7: =IF(InputOutput!$B40="","",InputOutput!BC26) | AL7: =IF(InputOutput!$B40="","",InputOutput!BD26) | AM7: =IF(InputOutput!$B40="","",InputOutput!BE26) | AN7: =IF(InputOutput!$B40="","",InputOutput!BF26)
A8: =IF(InputOutput!$B27="","",InputOutput!A27) -> 27 | B8: =IF(InputOutput!$B27="","",InputOutput!B27) -> 270 | C8: =IF(InputOutput!$B27="","",InputOutput!C27) -> 267 | D8: =IF(InputOutput!$B27="","",InputOutput!D27) -> 139 | E8: =IF(InputOutput!$B27="","",InputOutput!E27) -> 0 | F8: =IF(InputOutput!$B27="","",InputOutput!F27) -> 20 | G8: =IF(InputOutput!$B27="","",InputOutput!G27) -> 835 | H8: =IF(InputOutput!$B27="","",InputOutput!H27) -> 0 | ... AD8: =IF(InputOutput!$B27="","",InputOutput!AD27) -> 0 | AE8: =IF(InputOutput!$B27="","",ROUND(InputOutput!AW27,0)) -> 0 | AF8: =IF(InputOutput!$B27="","",ROUND(InputOutput!AX27,0)) -> 0 | AG8: =IF(InputOutput!$B27="","",InputOutput!AY27) -> 0 | AH8: =IF(InputOutput!$B27="","",InputOutput!AZ27) -> 0 | AI8: =IF(InputOutput!$B27="","",InputOutput!BA27) -> 0 | AJ8: =IF(InputOutput!$B27="","",InputOutput!BB27) -> 0 | AK8: =IF(InputOutput!$B27="","",InputOutput!BC27) -> 0 | AL8: =IF(InputOutput!$B27="","",InputOutput!BD27) -> 0 | AM8: =IF(InputOutput!$B27="","",InputOutput!BE27) -> 0 | AN8: =IF(InputOutput!$B27="","",InputOutput!BF27) -> 0
A9: =IF(InputOutput!$B28="","",InputOutput!A28) -> 28 | B9: =IF(InputOutput!$B28="","",InputOutput!B28) -> 270 | C9: =IF(InputOutput!$B28="","",InputOutput!C28) -> 267 | D9: =IF(InputOutput!$B28="","",InputOutput!D28) -> 139 | E9: =IF(InputOutput!$B28="","",InputOutput!E28) -> 0 | F9: =IF(InputOutput!$B28="","",InputOutput!F28) -> 20 | G9: =IF(InputOutput!$B28="","",InputOutput!G28) -> 835 | H9: =IF(InputOutput!$B28="","",InputOutput!H28) -> 0 | ... AD9: =IF(InputOutput!$B28="","",InputOutput!AD28) -> 0 | AE9: =IF(InputOutput!$B28="","",ROUND(InputOutput!AW28,0)) -> 0 | AF9: =IF(InputOutput!$B28="","",ROUND(InputOutput!AX28,0)) -> 0 | AG9: =IF(InputOutput!$B28="","",InputOutput!AY28) -> 0 | AH9: =IF(InputOutput!$B28="","",InputOutput!AZ28) -> 0 | AI9: =IF(InputOutput!$B28="","",InputOutput!BA28) -> 0 | AJ9: =IF(InputOutput!$B28="","",InputOutput!BB28) -> 0 | AK9: =IF(InputOutput!$B28="","",InputOutput!BC28) -> 0 | AL9: =IF(InputOutput!$B28="","",InputOutput!BD28) -> 0 | AM9: =IF(InputOutput!$B28="","",InputOutput!BE28) -> 0 | AN9: =IF(InputOutput!$B28="","",InputOutput!BF28) -> 0
A10: =IF(InputOutput!$B29="","",InputOutput!A29) -> 29 | B10: =IF(InputOutput!$B29="","",InputOutput!B29) -> 270 | C10: =IF(InputOutput!$B29="","",InputOutput!C29) -> 267 | D10: =IF(InputOutput!$B29="","",InputOutput!D29) -> 139 | E10: =IF(InputOutput!$B29="","",InputOutput!E29) -> 0 | F10: =IF(InputOutput!$B29="","",InputOutput!F29) -> 20 | G10: =IF(InputOutput!$B29="","",InputOutput!G29) -> 835 | H10: =IF(InputOutput!$B29="","",InputOutput!H29) -> 0 | ... AD10: =IF(InputOutput!$B29="","",InputOutput!AD29) -> 0 | AE10: =IF(InputOutput!$B29="","",ROUND(InputOutput!AW29,0)) -> 0 | AF10: =IF(InputOutput!$B29="","",ROUND(InputOutput!AX29,0)) -> 0 | AG10: =IF(InputOutput!$B29="","",InputOutput!AY29) -> 0 | AH10: =IF(InputOutput!$B29="","",InputOutput!AZ29) -> 0 | AI10: =IF(InputOutput!$B29="","",InputOutput!BA29) -> 0 | AJ10: =IF(InputOutput!$B29="","",InputOutput!BB29) -> 0 | AK10: =IF(InputOutput!$B29="","",InputOutput!BC29) -> 0 | AL10: =IF(InputOutput!$B29="","",InputOutput!BD29) -> 0 | AM10: =IF(InputOutput!$B29="","",InputOutput!BE29) -> 0 | AN10: =IF(InputOutput!$B29="","",InputOutput!BF29) -> 0
A11: =IF(InputOutput!$B30="","",InputOutput!A30) -> 30 | B11: =IF(InputOutput!$B30="","",InputOutput!B30) -> 235 | C11: =IF(InputOutput!$B30="","",InputOutput!C30) -> 232 | D11: =IF(InputOutput!$B30="","",InputOutput!D30) -> 104 | E11: =IF(InputOutput!$B30="","",InputOutput!E30) -> 0 | F11: =IF(InputOutput!$B30="","",InputOutput!F30) -> 20 | G11: =IF(InputOutput!$B30="","",InputOutput!G30) -> 660 | H11: =IF(InputOutput!$B30="","",InputOutput!H30) -> 0 | ... AD11: =IF(InputOutput!$B30="","",InputOutput!AD30) -> 0 | AE11: =IF(InputOutput!$B30="","",ROUND(InputOutput!AW30,0)) -> 0 | AF11: =IF(InputOutput!$B30="","",ROUND(InputOutput!AX30,0)) -> 0 | AG11: =IF(InputOutput!$B30="","",InputOutput!AY30) -> 0 | AH11: =IF(InputOutput!$B30="","",InputOutput!AZ30) -> 0 | AI11: =IF(InputOutput!$B30="","",InputOutput!BA30) -> 0 | AJ11: =IF(InputOutput!$B30="","",InputOutput!BB30) -> 0 | AK11: =IF(InputOutput!$B30="","",InputOutput!BC30) -> 0 | AL11: =IF(InputOutput!$B30="","",InputOutput!BD30) -> 0 | AM11: =IF(InputOutput!$B30="","",InputOutput!BE30) -> 0 | AN11: =IF(InputOutput!$B30="","",InputOutput!BF30) -> 0
A12: =IF(InputOutput!$B31="","",InputOutput!A31) -> 31 | B12: =IF(InputOutput!$B31="","",InputOutput!B31) -> 235 | C12: =IF(InputOutput!$B31="","",InputOutput!C31) -> 232 | D12: =IF(InputOutput!$B31="","",InputOutput!D31) -> 104 | E12: =IF(InputOutput!$B31="","",InputOutput!E31) -> 0 | F12: =IF(InputOutput!$B31="","",InputOutput!F31) -> 20 | G12: =IF(InputOutput!$B31="","",InputOutput!G31) -> 660 | H12: =IF(InputOutput!$B31="","",InputOutput!H31) -> 0 | ... AD12: =IF(InputOutput!$B31="","",InputOutput!AD31) -> 0 | AE12: =IF(InputOutput!$B31="","",ROUND(InputOutput!AW31,0)) -> 0 | AF12: =IF(InputOutput!$B31="","",ROUND(InputOutput!AX31,0)) -> 0 | AG12: =IF(InputOutput!$B31="","",InputOutput!AY31) -> 0 | AH12: =IF(InputOutput!$B31="","",InputOutput!AZ31) -> 0 | AI12: =IF(InputOutput!$B31="","",InputOutput!BA31) -> 0 | AJ12: =IF(InputOutput!$B31="","",InputOutput!BB31) -> 0 | AK12: =IF(InputOutput!$B31="","",InputOutput!BC31) -> 0 | AL12: =IF(InputOutput!$B31="","",InputOutput!BD31) -> 0 | AM12: =IF(InputOutput!$B31="","",InputOutput!BE31) -> 0 | AN12: =IF(InputOutput!$B31="","",InputOutput!BF31) -> 0
A13: =IF(InputOutput!$B32="","",InputOutput!A32) -> 32 | B13: =IF(InputOutput!$B32="","",InputOutput!B32) -> 235 | C13: =IF(InputOutput!$B32="","",InputOutput!C32) -> 232 | D13: =IF(InputOutput!$B32="","",InputOutput!D32) -> 104 | E13: =IF(InputOutput!$B32="","",InputOutput!E32) -> 0 | F13: =IF(InputOutput!$B32="","",InputOutput!F32) -> 20 | G13: =IF(InputOutput!$B32="","",InputOutput!G32) -> 660 | H13: =IF(InputOutput!$B32="","",InputOutput!H32) -> 0 | ... AD13: =IF(InputOutput!$B32="","",InputOutput!AD32) -> 0 | AE13: =IF(InputOutput!$B32="","",ROUND(InputOutput!AW32,0)) -> 0 | AF13: =IF(InputOutput!$B32="","",ROUND(InputOutput!AX32,0)) -> 0 | AG13: =IF(InputOutput!$B32="","",InputOutput!AY32) -> 0 | AH13: =IF(InputOutput!$B32="","",InputOutput!AZ32) -> 0 | AI13: =IF(InputOutput!$B32="","",InputOutput!BA32) -> 0 | AJ13: =IF(InputOutput!$B32="","",InputOutput!BB32) -> 0 | AK13: =IF(InputOutput!$B32="","",InputOutput!BC32) -> 0 | AL13: =IF(InputOutput!$B32="","",InputOutput!BD32) -> 0 | AM13: =IF(InputOutput!$B32="","",InputOutput!BE32) -> 0 | AN13: =IF(InputOutput!$B32="","",InputOutput!BF32) -> 0
A14: =IF(InputOutput!$B33="","",InputOutput!A33) -> 33 | B14: =IF(InputOutput!$B33="","",InputOutput!B33) -> 270 | C14: =IF(InputOutput!$B33="","",InputOutput!C33) -> 267 | D14: =IF(InputOutput!$B33="","",InputOutput!D33) -> 104 | E14: =IF(InputOutput!$B33="","",InputOutput!E33) -> 0 | F14: =IF(InputOutput!$B33="","",InputOutput!F33) -> 20 | G14: =IF(InputOutput!$B33="","",InputOutput!G33) -> 835 | H14: =IF(InputOutput!$B33="","",InputOutput!H33) -> 0 | ... AD14: =IF(InputOutput!$B33="","",InputOutput!AD33) -> 0 | AE14: =IF(InputOutput!$B33="","",ROUND(InputOutput!AW33,0)) -> 0 | AF14: =IF(InputOutput!$B33="","",ROUND(InputOutput!AX33,0)) -> 0 | AG14: =IF(InputOutput!$B33="","",InputOutput!AY33) -> 0 | AH14: =IF(InputOutput!$B33="","",InputOutput!AZ33) -> 0 | AI14: =IF(InputOutput!$B33="","",InputOutput!BA33) -> 0 | AJ14: =IF(InputOutput!$B33="","",InputOutput!BB33) -> 0 | AK14: =IF(InputOutput!$B33="","",InputOutput!BC33) -> 0 | AL14: =IF(InputOutput!$B33="","",InputOutput!BD33) -> 0 | AM14: =IF(InputOutput!$B33="","",InputOutput!BE33) -> 0 | AN14: =IF(InputOutput!$B33="","",InputOutput!BF33) -> 0
A15: =IF(InputOutput!$B34="","",InputOutput!A34) -> 34 | B15: =IF(InputOutput!$B34="","",InputOutput!B34) -> 270 | C15: =IF(InputOutput!$B34="","",InputOutput!C34) -> 267 | D15: =IF(InputOutput!$B34="","",InputOutput!D34) -> 104 | E15: =IF(InputOutput!$B34="","",InputOutput!E34) -> 0 | F15: =IF(InputOutput!$B34="","",InputOutput!F34) -> 20 | G15: =IF(InputOutput!$B34="","",InputOutput!G34) -> 835 | H15: =IF(InputOutput!$B34="","",InputOutput!H34) -> 0 | ... AD15: =IF(InputOutput!$B34="","",InputOutput!AD34) -> 0 | AE15: =IF(InputOutput!$B34="","",ROUND(InputOutput!AW34,0)) -> 0 | AF15: =IF(InputOutput!$B34="","",ROUND(InputOutput!AX34,0)) -> 0 | AG15: =IF(InputOutput!$B34="","",InputOutput!AY34) -> 0 | AH15: =IF(InputOutput!$B34="","",InputOutput!AZ34) -> 0 | AI15: =IF(InputOutput!$B34="","",InputOutput!BA34) -> 0 | AJ15: =IF(InputOutput!$B34="","",InputOutput!BB34) -> 0 | AK15: =IF(InputOutput!$B34="","",InputOutput!BC34) -> 0 | AL15: =IF(InputOutput!$B34="","",InputOutput!BD34) -> 0 | AM15: =IF(InputOutput!$B34="","",InputOutput!BE34) -> 0 | AN15: =IF(InputOutput!$B34="","",InputOutput!BF34) -> 0
A16: =IF(InputOutput!$B35="","",InputOutput!A35) -> 35 | B16: =IF(InputOutput!$B35="","",InputOutput!B35) -> 270 | C16: =IF(InputOutput!$B35="","",InputOutput!C35) -> 267 | D16: =IF(InputOutput!$B35="","",InputOutput!D35) -> 104 | E16: =IF(InputOutput!$B35="","",InputOutput!E35) -> 0 | F16: =IF(InputOutput!$B35="","",InputOutput!F35) -> 20 | G16: =IF(InputOutput!$B35="","",InputOutput!G35) -> 835 | H16: =IF(InputOutput!$B35="","",InputOutput!H35) -> 0 | ... AD16: =IF(InputOutput!$B35="","",InputOutput!AD35) -> 0 | AE16: =IF(InputOutput!$B35="","",ROUND(InputOutput!AW35,0)) -> 0 | AF16: =IF(InputOutput!$B35="","",ROUND(InputOutput!AX35,0)) -> 0 | AG16: =IF(InputOutput!$B35="","",InputOutput!AY35) -> 0 | AH16: =IF(InputOutput!$B35="","",InputOutput!AZ35) -> 0 | AI16: =IF(InputOutput!$B35="","",InputOutput!BA35) -> 0 | AJ16: =IF(InputOutput!$B35="","",InputOutput!BB35) -> 0 | AK16: =IF(InputOutput!$B35="","",InputOutput!BC35) -> 0 | AL16: =IF(InputOutput!$B35="","",InputOutput!BD35) -> 0 | AM16: =IF(InputOutput!$B35="","",InputOutput!BE35) -> 0 | AN16: =IF(InputOutput!$B35="","",InputOutput!BF35) -> 0
A17: =IF(InputOutput!$B36="","",InputOutput!A36) -> 36 | B17: =IF(InputOutput!$B36="","",InputOutput!B36) -> 270 | C17: =IF(InputOutput!$B36="","",InputOutput!C36) -> 267 | D17: =IF(InputOutput!$B36="","",InputOutput!D36) -> 139 | E17: =IF(InputOutput!$B36="","",InputOutput!E36) -> 0 | F17: =IF(InputOutput!$B36="","",InputOutput!F36) -> 20 | G17: =IF(InputOutput!$B36="","",InputOutput!G36) -> 835 | H17: =IF(InputOutput!$B36="","",InputOutput!H36) -> 0 | ... AD17: =IF(InputOutput!$B36="","",InputOutput!AD36) -> 0 | AE17: =IF(InputOutput!$B36="","",ROUND(InputOutput!AW36,0)) -> 0 | AF17: =IF(InputOutput!$B36="","",ROUND(InputOutput!AX36,0)) -> 0 | AG17: =IF(InputOutput!$B36="","",InputOutput!AY36) -> 0 | AH17: =IF(InputOutput!$B36="","",InputOutput!AZ36) -> 0 | AI17: =IF(InputOutput!$B36="","",InputOutput!BA36) -> 0 | AJ17: =IF(InputOutput!$B36="","",InputOutput!BB36) -> 0 | AK17: =IF(InputOutput!$B36="","",InputOutput!BC36) -> 0 | AL17: =IF(InputOutput!$B36="","",InputOutput!BD36) -> 0 | AM17: =IF(InputOutput!$B36="","",InputOutput!BE36) -> 0 | AN17: =IF(InputOutput!$B36="","",InputOutput!BF36) -> 0
A18: =IF(InputOutput!#REF!="","",InputOutput!A37) -> #REF! | B18: =IF(InputOutput!#REF!="","",InputOutput!#REF!) -> #REF! | C18: =IF(InputOutput!#REF!="","",InputOutput!#REF!) -> #REF! | D18: =IF(InputOutput!#REF!="","",InputOutput!#REF!) -> #REF! | E18: =IF(InputOutput!#REF!="","",InputOutput!#REF!) -> #REF! | F18: =IF(InputOutput!#REF!="","",InputOutput!#REF!) -> #REF! | G18: =IF(InputOutput!#REF!="","",InputOutput!#REF!) -> #REF! | H18: =IF(InputOutput!#REF!="","",InputOutput!#REF!) -> #REF! | I18: =IF(InputOutput!#REF!="","",InputOutput!#REF!) -> #REF! | ... Q18: =IF(InputOutput!#REF!="","",InputOutput!#REF!) -> #REF! | R18: =IF(InputOutput!#REF!="","",InputOutput!R37) -> #REF! | S18: =IF(InputOutput!#REF!="","",InputOutput!S37) -> #REF! | T18: =IF(InputOutput!#REF!="","",InputOutput!T37) -> #REF! | U18: =IF(InputOutput!#REF!="","",InputOutput!U37) -> #REF! | V18: =IF(InputOutput!#REF!="","",InputOutput!V37) -> #REF! | W18: =IF(InputOutput!#REF!="","",InputOutput!W37) -> #REF! | X18: =IF(InputOutput!#REF!="","",InputOutput!X37) -> #REF! | Y18: =IF(InputOutput!#REF!="","",InputOutput!Y37) -> #REF! | ... AD18: =IF(InputOutput!#REF!="","",InputOutput!AD37) -> #REF! | AE18: =IF(InputOutput!#REF!="","",ROUND(InputOutput!AW37,0)) -> #REF! | AF18: =IF(InputOutput!#REF!="","",ROUND(InputOutput!AX37,0)) -> #REF! | AG18: =IF(InputOutput!#REF!="","",InputOutput!AY37) -> #REF! | AH18: =IF(InputOutput!#REF!="","",InputOutput!AZ37) -> #REF! | AI18: =IF(InputOutput!#REF!="","",InputOutput!BA37) -> #REF! | AJ18: =IF(InputOutput!#REF!="","",InputOutput!BB37) -> #REF! | AK18: =IF(InputOutput!#REF!="","",InputOutput!BC37) -> #REF! | AL18: =IF(InputOutput!#REF!="","",InputOutput!BD37) -> #REF! | AM18: =IF(InputOutput!#REF!="","",InputOutput!BE37) -> #REF! | AN18: =IF(InputOutput!#REF!="","",InputOutput!BF37) -> #REF!
A19: =IF(InputOutput!#REF!="","",InputOutput!A38) -> #REF! | B19: =IF(InputOutput!#REF!="","",InputOutput!#REF!) -> #REF! | C19: =IF(InputOutput!#REF!="","",InputOutput!#REF!) -> #REF! | D19: =IF(InputOutput!#REF!="","",InputOutput!#REF!) -> #REF! | E19: =IF(InputOutput!#REF!="","",InputOutput!#REF!) -> #REF! | F19: =IF(InputOutput!#REF!="","",InputOutput!#REF!) -> #REF! | G19: =IF(InputOutput!#REF!="","",InputOutput!#REF!) -> #REF! | H19: =IF(InputOutput!#REF!="","",InputOutput!#REF!) -> #REF! | I19: =IF(InputOutput!#REF!="","",InputOutput!#REF!) -> #REF! | ... Q19: =IF(InputOutput!#REF!="","",InputOutput!#REF!) -> #REF! | R19: =IF(InputOutput!#REF!="","",InputOutput!R38) -> #REF! | S19: =IF(InputOutput!#REF!="","",InputOutput!S38) -> #REF! | T19: =IF(InputOutput!#REF!="","",InputOutput!T38) -> #REF! | U19: =IF(InputOutput!#REF!="","",InputOutput!U38) -> #REF! | V19: =IF(InputOutput!#REF!="","",InputOutput!V38) -> #REF! | W19: =IF(InputOutput!#REF!="","",InputOutput!W38) -> #REF! | X19: =IF(InputOutput!#REF!="","",InputOutput!X38) -> #REF! | Y19: =IF(InputOutput!#REF!="","",InputOutput!Y38) -> #REF! | ... AD19: =IF(InputOutput!#REF!="","",InputOutput!AD38) -> #REF! | AE19: =IF(InputOutput!#REF!="","",ROUND(InputOutput!AW38,0)) -> #REF! | AF19: =IF(InputOutput!#REF!="","",ROUND(InputOutput!AX38,0)) -> #REF! | AG19: =IF(InputOutput!#REF!="","",InputOutput!AY38) -> #REF! | AH19: =IF(InputOutput!#REF!="","",InputOutput!AZ38) -> #REF! | AI19: =IF(InputOutput!#REF!="","",InputOutput!BA38) -> #REF! | AJ19: =IF(InputOutput!#REF!="","",InputOutput!BB38) -> #REF! | AK19: =IF(InputOutput!#REF!="","",InputOutput!BC38) -> #REF! | AL19: =IF(InputOutput!#REF!="","",InputOutput!BD38) -> #REF! | AM19: =IF(InputOutput!#REF!="","",InputOutput!BE38) -> #REF! | AN19: =IF(InputOutput!#REF!="","",InputOutput!BF38) -> #REF!
A20: =IF(InputOutput!#REF!="","",InputOutput!A39) -> #REF! | B20: =IF(InputOutput!#REF!="","",InputOutput!#REF!) -> #REF! | C20: =IF(InputOutput!#REF!="","",InputOutput!#REF!) -> #REF! | D20: =IF(InputOutput!#REF!="","",InputOutput!#REF!) -> #REF! | E20: =IF(InputOutput!#REF!="","",InputOutput!#REF!) -> #REF! | F20: =IF(InputOutput!#REF!="","",InputOutput!#REF!) -> #REF! | G20: =IF(InputOutput!#REF!="","",InputOutput!#REF!) -> #REF! | H20: =IF(InputOutput!#REF!="","",InputOutput!#REF!) -> #REF! | I20: =IF(InputOutput!#REF!="","",InputOutput!#REF!) -> #REF! | ... Q20: =IF(InputOutput!#REF!="","",InputOutput!#REF!) -> #REF! | R20: =IF(InputOutput!#REF!="","",InputOutput!R39) -> #REF! | S20: =IF(InputOutput!#REF!="","",InputOutput!S39) -> #REF! | T20: =IF(InputOutput!#REF!="","",InputOutput!T39) -> #REF! | U20: =IF(InputOutput!#REF!="","",InputOutput!U39) -> #REF! | V20: =IF(InputOutput!#REF!="","",InputOutput!V39) -> #REF! | W20: =IF(InputOutput!#REF!="","",InputOutput!W39) -> #REF! | X20: =IF(InputOutput!#REF!="","",InputOutput!X39) -> #REF! | Y20: =IF(InputOutput!#REF!="","",InputOutput!Y39) -> #REF! | ... AD20: =IF(InputOutput!#REF!="","",InputOutput!AD39) -> #REF! | AE20: =IF(InputOutput!#REF!="","",ROUND(InputOutput!AW39,0)) -> #REF! | AF20: =IF(InputOutput!#REF!="","",ROUND(InputOutput!AX39,0)) -> #REF! | AG20: =IF(InputOutput!#REF!="","",InputOutput!AY39) -> #REF! | AH20: =IF(InputOutput!#REF!="","",InputOutput!AZ39) -> #REF! | AI20: =IF(InputOutput!#REF!="","",InputOutput!BA39) -> #REF! | AJ20: =IF(InputOutput!#REF!="","",InputOutput!BB39) -> #REF! | AK20: =IF(InputOutput!#REF!="","",InputOutput!BC39) -> #REF! | AL20: =IF(InputOutput!#REF!="","",InputOutput!BD39) -> #REF! | AM20: =IF(InputOutput!#REF!="","",InputOutput!BE39) -> #REF! | AN20: =IF(InputOutput!#REF!="","",InputOutput!BF39) -> #REF!
A21: =IF(InputOutput!#REF!="","",InputOutput!A40) -> #REF! | B21: =IF(InputOutput!#REF!="","",InputOutput!#REF!) -> #REF! | C21: =IF(InputOutput!#REF!="","",InputOutput!#REF!) -> #REF! | D21: =IF(InputOutput!#REF!="","",InputOutput!#REF!) -> #REF! | E21: =IF(InputOutput!#REF!="","",InputOutput!#REF!) -> #REF! | F21: =IF(InputOutput!#REF!="","",InputOutput!#REF!) -> #REF! | G21: =IF(InputOutput!#REF!="","",InputOutput!#REF!) -> #REF! | H21: =IF(InputOutput!#REF!="","",InputOutput!#REF!) -> #REF! | I21: =IF(InputOutput!#REF!="","",InputOutput!#REF!) -> #REF! | ... Q21: =IF(InputOutput!#REF!="","",InputOutput!#REF!) -> #REF! | R21: =IF(InputOutput!#REF!="","",InputOutput!R40) -> #REF! | S21: =IF(InputOutput!#REF!="","",InputOutput!S40) -> #REF! | T21: =IF(InputOutput!#REF!="","",InputOutput!T40) -> #REF! | U21: =IF(InputOutput!#REF!="","",InputOutput!U40) -> #REF! | V21: =IF(InputOutput!#REF!="","",InputOutput!V40) -> #REF! | W21: =IF(InputOutput!#REF!="","",InputOutput!W40) -> #REF! | X21: =IF(InputOutput!#REF!="","",InputOutput!X40) -> #REF! | Y21: =IF(InputOutput!#REF!="","",InputOutput!Y40) -> #REF! | ... AD21: =IF(InputOutput!#REF!="","",InputOutput!AD40) -> #REF! | AE21: =IF(InputOutput!#REF!="","",ROUND(InputOutput!AW40,0)) -> #REF! | AF21: =IF(InputOutput!#REF!="","",ROUND(InputOutput!AX40,0)) -> #REF! | AG21: =IF(InputOutput!#REF!="","",InputOutput!AY40) -> #REF! | AH21: =IF(InputOutput!#REF!="","",InputOutput!AZ40) -> #REF! | AI21: =IF(InputOutput!#REF!="","",InputOutput!BA40) -> #REF! | AJ21: =IF(InputOutput!#REF!="","",InputOutput!BB40) -> #REF! | AK21: =IF(InputOutput!#REF!="","",InputOutput!BC40) -> #REF! | AL21: =IF(InputOutput!#REF!="","",InputOutput!BD40) -> #REF! | AM21: =IF(InputOutput!#REF!="","",InputOutput!BE40) -> #REF! | AN21: =IF(InputOutput!#REF!="","",InputOutput!BF40) -> #REF!
A22: =IF(InputOutput!$B41="","",InputOutput!A41) | B22: =IF(InputOutput!$B41="","",InputOutput!B41) | C22: =IF(InputOutput!$B41="","",InputOutput!C41) | D22: =IF(InputOutput!$B41="","",InputOutput!D41) | E22: =IF(InputOutput!$B41="","",InputOutput!E41) | F22: =IF(InputOutput!$B41="","",InputOutput!F41) | G22: =IF(InputOutput!$B41="","",InputOutput!G41) | H22: =IF(InputOutput!$B41="","",InputOutput!H41) | ... AD22: =IF(InputOutput!$B41="","",InputOutput!AD41) | AE22: =IF(InputOutput!$B41="","",ROUND(InputOutput!AW41,0)) | AF22: =IF(InputOutput!$B41="","",ROUND(InputOutput!AX41,0)) | AG22: =IF(InputOutput!$B41="","",InputOutput!AY41) | AH22: =IF(InputOutput!$B41="","",InputOutput!AZ41) | AI22: =IF(InputOutput!$B41="","",InputOutput!BA41) | AJ22: =IF(InputOutput!$B41="","",InputOutput!BB41) | AK22: =IF(InputOutput!$B41="","",InputOutput!BC41) | AL22: =IF(InputOutput!$B41="","",InputOutput!BD41) | AM22: =IF(InputOutput!$B41="","",InputOutput!BE41) | AN22: =IF(InputOutput!$B41="","",InputOutput!BF41)
A23: =IF(InputOutput!$B42="","",InputOutput!A42) | B23: =IF(InputOutput!$B42="","",InputOutput!B42) | C23: =IF(InputOutput!$B42="","",InputOutput!C42) | D23: =IF(InputOutput!$B42="","",InputOutput!D42) | E23: =IF(InputOutput!$B42="","",InputOutput!E42) | F23: =IF(InputOutput!$B42="","",InputOutput!F42) | G23: =IF(InputOutput!$B42="","",InputOutput!G42) | H23: =IF(InputOutput!$B42="","",InputOutput!H42) | ... AD23: =IF(InputOutput!$B42="","",InputOutput!AD42) | AE23: =IF(InputOutput!$B42="","",ROUND(InputOutput!AW42,0)) | AF23: =IF(InputOutput!$B42="","",ROUND(InputOutput!AX42,0)) | AG23: =IF(InputOutput!$B42="","",InputOutput!AY42) | AH23: =IF(InputOutput!$B42="","",InputOutput!AZ42) | AI23: =IF(InputOutput!$B42="","",InputOutput!BA42) | AJ23: =IF(InputOutput!$B42="","",InputOutput!BB42) | AK23: =IF(InputOutput!$B42="","",InputOutput!BC42) | AL23: =IF(InputOutput!$B42="","",InputOutput!BD42) | AM23: =IF(InputOutput!$B42="","",InputOutput!BE42) | AN23: =IF(InputOutput!$B42="","",InputOutput!BF42)
A24: =IF(InputOutput!$B43="","",InputOutput!A43) | B24: =IF(InputOutput!$B43="","",InputOutput!B43) | C24: =IF(InputOutput!$B43="","",InputOutput!C43) | D24: =IF(InputOutput!$B43="","",InputOutput!D43) | E24: =IF(InputOutput!$B43="","",InputOutput!E43) | F24: =IF(InputOutput!$B43="","",InputOutput!F43) | G24: =IF(InputOutput!$B43="","",InputOutput!G43) | H24: =IF(InputOutput!$B43="","",InputOutput!H43) | ... AD24: =IF(InputOutput!$B43="","",InputOutput!AD43) | AE24: =IF(InputOutput!$B43="","",ROUND(InputOutput!AW43,0)) | AF24: =IF(InputOutput!$B43="","",ROUND(InputOutput!AX43,0)) | AG24: =IF(InputOutput!$B43="","",InputOutput!AY43) | AH24: =IF(InputOutput!$B43="","",InputOutput!AZ43) | AI24: =IF(InputOutput!$B43="","",InputOutput!BA43) | AJ24: =IF(InputOutput!$B43="","",InputOutput!BB43) | AK24: =IF(InputOutput!$B43="","",InputOutput!BC43) | AL24: =IF(InputOutput!$B43="","",InputOutput!BD43) | AM24: =IF(InputOutput!$B43="","",InputOutput!BE43) | AN24: =IF(InputOutput!$B43="","",InputOutput!BF43)
A25: =IF(InputOutput!$B44="","",InputOutput!A44) | B25: =IF(InputOutput!$B44="","",InputOutput!B44) | C25: =IF(InputOutput!$B44="","",InputOutput!C44) | D25: =IF(InputOutput!$B44="","",InputOutput!D44) | E25: =IF(InputOutput!$B44="","",InputOutput!E44) | F25: =IF(InputOutput!$B44="","",InputOutput!F44) | G25: =IF(InputOutput!$B44="","",InputOutput!G44) | H25: =IF(InputOutput!$B44="","",InputOutput!H44) | ... AD25: =IF(InputOutput!$B44="","",InputOutput!AD44) | AE25: =IF(InputOutput!$B44="","",ROUND(InputOutput!AW44,0)) | AF25: =IF(InputOutput!$B44="","",ROUND(InputOutput!AX44,0)) | AG25: =IF(InputOutput!$B44="","",InputOutput!AY44) | AH25: =IF(InputOutput!$B44="","",InputOutput!AZ44) | AI25: =IF(InputOutput!$B44="","",InputOutput!BA44) | AJ25: =IF(InputOutput!$B44="","",InputOutput!BB44) | AK25: =IF(InputOutput!$B44="","",InputOutput!BC44) | AL25: =IF(InputOutput!$B44="","",InputOutput!BD44) | AM25: =IF(InputOutput!$B44="","",InputOutput!BE44) | AN25: =IF(InputOutput!$B44="","",InputOutput!BF44)
A26: =IF(InputOutput!$B45="","",InputOutput!A45) | B26: =IF(InputOutput!$B45="","",InputOutput!B45) | C26: =IF(InputOutput!$B45="","",InputOutput!C45) | D26: =IF(InputOutput!$B45="","",InputOutput!D45) | E26: =IF(InputOutput!$B45="","",InputOutput!E45) | F26: =IF(InputOutput!$B45="","",InputOutput!F45) | G26: =IF(InputOutput!$B45="","",InputOutput!G45) | H26: =IF(InputOutput!$B45="","",InputOutput!H45) | ... AD26: =IF(InputOutput!$B45="","",InputOutput!AD45) | AE26: =IF(InputOutput!$B45="","",ROUND(InputOutput!AW45,0)) | AF26: =IF(InputOutput!$B45="","",ROUND(InputOutput!AX45,0)) | AG26: =IF(InputOutput!$B45="","",InputOutput!AY45) | AH26: =IF(InputOutput!$B45="","",InputOutput!AZ45) | AI26: =IF(InputOutput!$B45="","",InputOutput!BA45) | AJ26: =IF(InputOutput!$B45="","",InputOutput!BB45) | AK26: =IF(InputOutput!$B45="","",InputOutput!BC45) | AL26: =IF(InputOutput!$B45="","",InputOutput!BD45) | AM26: =IF(InputOutput!$B45="","",InputOutput!BE45) | AN26: =IF(InputOutput!$B45="","",InputOutput!BF45)
A27: =IF(InputOutput!$B46="","",InputOutput!A46) | B27: =IF(InputOutput!$B46="","",InputOutput!B46) | C27: =IF(InputOutput!$B46="","",InputOutput!C46) | D27: =IF(InputOutput!$B46="","",InputOutput!D46) | E27: =IF(InputOutput!$B46="","",InputOutput!E46) | F27: =IF(InputOutput!$B46="","",InputOutput!F46) | G27: =IF(InputOutput!$B46="","",InputOutput!G46) | H27: =IF(InputOutput!$B46="","",InputOutput!H46) | ... AD27: =IF(InputOutput!$B46="","",InputOutput!AD46) | AE27: =IF(InputOutput!$B46="","",ROUND(InputOutput!AW46,0)) | AF27: =IF(InputOutput!$B46="","",ROUND(InputOutput!AX46,0)) | AG27: =IF(InputOutput!$B46="","",InputOutput!AY46) | AH27: =IF(InputOutput!$B46="","",InputOutput!AZ46) | AI27: =IF(InputOutput!$B46="","",InputOutput!BA46) | AJ27: =IF(InputOutput!$B46="","",InputOutput!BB46) | AK27: =IF(InputOutput!$B46="","",InputOutput!BC46) | AL27: =IF(InputOutput!$B46="","",InputOutput!BD46) | AM27: =IF(InputOutput!$B46="","",InputOutput!BE46) | AN27: =IF(InputOutput!$B46="","",InputOutput!BF46)
A28: =IF(InputOutput!$B47="","",InputOutput!A47) | B28: =IF(InputOutput!$B47="","",InputOutput!B47) | C28: =IF(InputOutput!$B47="","",InputOutput!C47) | D28: =IF(InputOutput!$B47="","",InputOutput!D47) | E28: =IF(InputOutput!$B47="","",InputOutput!E47) | F28: =IF(InputOutput!$B47="","",InputOutput!F47) | G28: =IF(InputOutput!$B47="","",InputOutput!G47) | H28: =IF(InputOutput!$B47="","",InputOutput!H47) | ... AD28: =IF(InputOutput!$B47="","",InputOutput!AD47) | AE28: =IF(InputOutput!$B47="","",ROUND(InputOutput!AW47,0)) | AF28: =IF(InputOutput!$B47="","",ROUND(InputOutput!AX47,0)) | AG28: =IF(InputOutput!$B47="","",InputOutput!AY47) | AH28: =IF(InputOutput!$B47="","",InputOutput!AZ47) | AI28: =IF(InputOutput!$B47="","",InputOutput!BA47) | AJ28: =IF(InputOutput!$B47="","",InputOutput!BB47) | AK28: =IF(InputOutput!$B47="","",InputOutput!BC47) | AL28: =IF(InputOutput!$B47="","",InputOutput!BD47) | AM28: =IF(InputOutput!$B47="","",InputOutput!BE47) | AN28: =IF(InputOutput!$B47="","",InputOutput!BF47)
A29: =IF(InputOutput!$B48="","",InputOutput!A48) -> 48 | B29: =IF(InputOutput!$B48="","",InputOutput!B48) -> 0 | C29: =IF(InputOutput!$B48="","",InputOutput!C48) -> 1 | D29: =IF(InputOutput!$B48="","",InputOutput!D48) -> 1 | E29: =IF(InputOutput!$B48="","",InputOutput!E48) -> 1 | F29: =IF(InputOutput!$B48="","",InputOutput!F48) -> 4 | G29: =IF(InputOutput!$B48="","",InputOutput!G48) -> 0 | H29: =IF(InputOutput!$B48="","",InputOutput!H48) -> 60 | ... AD29: =IF(InputOutput!$B48="","",InputOutput!AD48) -> 1 | AE29: =IF(InputOutput!$B48="","",ROUND(InputOutput!AW48,0)) -> 1564 | AF29: =IF(InputOutput!$B48="","",ROUND(InputOutput!AX48,0)) -> 1086 | AG29: =IF(InputOutput!$B48="","",InputOutput!AY48) -> 500 | AH29: =IF(InputOutput!$B48="","",InputOutput!AZ48) -> SW00101 | AI29: =IF(InputOutput!$B48="","",InputOutput!BA48) -> kk | AJ29: =IF(InputOutput!$B48="","",InputOutput!BB48) -> Bergsko KK 270-110 4D20 SW00101 | AK29: =IF(InputOutput!$B48="","",InputOutput!BC48) -> 70 | AL29: =IF(InputOutput!$B48="","",InputOutput!BD48) -> 265 | AM29: =IF(InputOutput!$B48="","",InputOutput!BE48) -> 60 | AN29: =IF(InputOutput!$B48="","",InputOutput!BF48) -> 0
A30: =IF(InputOutput!$B49="","",InputOutput!A49) -> 49 | B30: =IF(InputOutput!$B49="","",InputOutput!B49) -> 0 | C30: =IF(InputOutput!$B49="","",InputOutput!C49) -> 1 | D30: =IF(InputOutput!$B49="","",InputOutput!D49) -> 0.9 | E30: =IF(InputOutput!$B49="","",InputOutput!E49) -> 1 | F30: =IF(InputOutput!$B49="","",InputOutput!F49) -> 4 | G30: =IF(InputOutput!$B49="","",InputOutput!G49) -> 0 | H30: =IF(InputOutput!$B49="","",InputOutput!H49) -> 60 | ... AD30: =IF(InputOutput!$B49="","",InputOutput!AD49) -> 1 | AE30: =IF(InputOutput!$B49="","",ROUND(InputOutput!AW49,0)) -> 1564 | AF30: =IF(InputOutput!$B49="","",ROUND(InputOutput!AX49,0)) -> 1086 | AG30: =IF(InputOutput!$B49="","",InputOutput!AY49) -> 500 | AH30: =IF(InputOutput!$B49="","",InputOutput!AZ49) -> SW00101 | AI30: =IF(InputOutput!$B49="","",InputOutput!BA49) -> kk | AJ30: =IF(InputOutput!$B49="","",InputOutput!BB49) -> Bergsko KK 270-110 4D20 SW00101 | AK30: =IF(InputOutput!$B49="","",InputOutput!BC49) -> 70 | AL30: =IF(InputOutput!$B49="","",InputOutput!BD49) -> 265 | AM30: =IF(InputOutput!$B49="","",InputOutput!BE49) -> 60 | AN30: =IF(InputOutput!$B49="","",InputOutput!BF49) -> 0
A31: =IF(InputOutput!$B50="","",InputOutput!A50) -> 50 | B31: =IF(InputOutput!$B50="","",InputOutput!B50) -> 0 | C31: =IF(InputOutput!$B50="","",InputOutput!C50) -> 1 | D31: =IF(InputOutput!$B50="","",InputOutput!D50) -> 0.8 | E31: =IF(InputOutput!$B50="","",InputOutput!E50) -> 1 | F31: =IF(InputOutput!$B50="","",InputOutput!F50) -> 4 | G31: =IF(InputOutput!$B50="","",InputOutput!G50) -> 0 | H31: =IF(InputOutput!$B50="","",InputOutput!H50) -> 60 | ... AD31: =IF(InputOutput!$B50="","",InputOutput!AD50) -> 1 | AE31: =IF(InputOutput!$B50="","",ROUND(InputOutput!AW50,0)) -> 1564 | AF31: =IF(InputOutput!$B50="","",ROUND(InputOutput!AX50,0)) -> 1086 | AG31: =IF(InputOutput!$B50="","",InputOutput!AY50) -> 500 | AH31: =IF(InputOutput!$B50="","",InputOutput!AZ50) -> SW00101 | AI31: =IF(InputOutput!$B50="","",InputOutput!BA50) -> kk | AJ31: =IF(InputOutput!$B50="","",InputOutput!BB50) -> Bergsko KK 270-110 4D20 SW00101 | AK31: =IF(InputOutput!$B50="","",InputOutput!BC50) -> 70 | AL31: =IF(InputOutput!$B50="","",InputOutput!BD50) -> 265 | AM31: =IF(InputOutput!$B50="","",InputOutput!BE50) -> 60 | AN31: =IF(InputOutput!$B50="","",InputOutput!BF50) -> 0
A32: =IF(InputOutput!$B51="","",InputOutput!A51) -> 51 | B32: =IF(InputOutput!$B51="","",InputOutput!B51) -> 0 | C32: =IF(InputOutput!$B51="","",InputOutput!C51) -> 0.9 | D32: =IF(InputOutput!$B51="","",InputOutput!D51) -> 1 | E32: =IF(InputOutput!$B51="","",InputOutput!E51) -> 1 | F32: =IF(InputOutput!$B51="","",InputOutput!F51) -> 4 | G32: =IF(InputOutput!$B51="","",InputOutput!G51) -> 0 | H32: =IF(InputOutput!$B51="","",InputOutput!H51) -> 60 | ... AD32: =IF(InputOutput!$B51="","",InputOutput!AD51) -> 1 | AE32: =IF(InputOutput!$B51="","",ROUND(InputOutput!AW51,0)) -> 1452 | AF32: =IF(InputOutput!$B51="","",ROUND(InputOutput!AX51,0)) -> 978 | AG32: =IF(InputOutput!$B51="","",InputOutput!AY51) -> 500 | AH32: =IF(InputOutput!$B51="","",InputOutput!AZ51) -> SW00101 | AI32: =IF(InputOutput!$B51="","",InputOutput!BA51) -> kk | AJ32: =IF(InputOutput!$B51="","",InputOutput!BB51) -> Bergsko KK 270-110 4D20 SW00101 | AK32: =IF(InputOutput!$B51="","",InputOutput!BC51) -> 70 | AL32: =IF(InputOutput!$B51="","",InputOutput!BD51) -> 265 | AM32: =IF(InputOutput!$B51="","",InputOutput!BE51) -> 60 | AN32: =IF(InputOutput!$B51="","",InputOutput!BF51) -> 0
A33: =IF(InputOutput!$B52="","",InputOutput!A52) -> 52 | B33: =IF(InputOutput!$B52="","",InputOutput!B52) -> 0 | C33: =IF(InputOutput!$B52="","",InputOutput!C52) -> 0.9 | D33: =IF(InputOutput!$B52="","",InputOutput!D52) -> 0.9 | E33: =IF(InputOutput!$B52="","",InputOutput!E52) -> 1 | F33: =IF(InputOutput!$B52="","",InputOutput!F52) -> 4 | G33: =IF(InputOutput!$B52="","",InputOutput!G52) -> 0 | H33: =IF(InputOutput!$B52="","",InputOutput!H52) -> 60 | ... AD33: =IF(InputOutput!$B52="","",InputOutput!AD52) -> 1 | AE33: =IF(InputOutput!$B52="","",ROUND(InputOutput!AW52,0)) -> 1452 | AF33: =IF(InputOutput!$B52="","",ROUND(InputOutput!AX52,0)) -> 978 | AG33: =IF(InputOutput!$B52="","",InputOutput!AY52) -> 500 | AH33: =IF(InputOutput!$B52="","",InputOutput!AZ52) -> SW00101 | AI33: =IF(InputOutput!$B52="","",InputOutput!BA52) -> kk | AJ33: =IF(InputOutput!$B52="","",InputOutput!BB52) -> Bergsko KK 270-110 4D20 SW00101 | AK33: =IF(InputOutput!$B52="","",InputOutput!BC52) -> 70 | AL33: =IF(InputOutput!$B52="","",InputOutput!BD52) -> 265 | AM33: =IF(InputOutput!$B52="","",InputOutput!BE52) -> 60 | AN33: =IF(InputOutput!$B52="","",InputOutput!BF52) -> 0
... A649: =IF(InputOutput!$B668="","",InputOutput!A668) -> 668 | B649: =IF(InputOutput!$B668="","",InputOutput!B668) -> 2.4 | C649: =IF(InputOutput!$B668="","",InputOutput!C668) -> 0.8 | D649: =IF(InputOutput!$B668="","",InputOutput!D668) -> 0.8 | E649: =IF(InputOutput!$B668="","",InputOutput!E668) -> 1 | F649: =IF(InputOutput!$B668="","",InputOutput!F668) -> 4 | G649: =IF(InputOutput!$B668="","",InputOutput!G668) -> 0 | H649: =IF(InputOutput!$B668="","",InputOutput!H668) -> 80 | ... AD649: =IF(InputOutput!$B668="","",InputOutput!AD668) -> 1 | AE649: =IF(InputOutput!$B668="","",ROUND(InputOutput!AW668,0)) -> 1732 | AF649: =IF(InputOutput!$B668="","",ROUND(InputOutput!AX668,0)) -> 1029 | AG649: =IF(InputOutput!$B668="","",InputOutput!AY668) -> 500 | AH649: =IF(InputOutput!$B668="","",InputOutput!AZ668) -> SW00213 | AI649: =IF(InputOutput!$B668="","",InputOutput!BA668) -> kk | AJ649: =IF(InputOutput!$B668="","",InputOutput!BB668) -> Bergsko KK 350-180 4D20 SW00213 | AK649: =IF(InputOutput!$B668="","",InputOutput!BC668) -> 70 | AL649: =IF(InputOutput!$B668="","",InputOutput!BD668) -> 345 | AM649: =IF(InputOutput!$B668="","",InputOutput!BE668) -> 50 | AN649: =IF(InputOutput!$B668="","",InputOutput!BF668) -> 120
A650: =IF(InputOutput!#REF!="","",InputOutput!#REF!) -> #REF! | B650: =IF(InputOutput!#REF!="","",InputOutput!#REF!) -> #REF! | C650: =IF(InputOutput!#REF!="","",InputOutput!#REF!) -> #REF! | D650: =IF(InputOutput!#REF!="","",InputOutput!#REF!) -> #REF! | E650: =IF(InputOutput!#REF!="","",InputOutput!#REF!) -> #REF! | F650: =IF(InputOutput!#REF!="","",InputOutput!#REF!) -> #REF! | G650: =IF(InputOutput!#REF!="","",InputOutput!#REF!) -> #REF! | H650: =IF(InputOutput!#REF!="","",InputOutput!#REF!) -> #REF! | ... AD650: =IF(InputOutput!#REF!="","",InputOutput!#REF!) -> #REF! | AE650: =IF(InputOutput!#REF!="","",ROUND(InputOutput!#REF!,0)) -> #REF! | AF650: =IF(InputOutput!#REF!="","",ROUND(InputOutput!#REF!,0)) -> #REF! | AG650: =IF(InputOutput!#REF!="","",InputOutput!#REF!) -> #REF! | AH650: =IF(InputOutput!#REF!="","",InputOutput!#REF!) -> #REF! | AI650: =IF(InputOutput!#REF!="","",InputOutput!#REF!) -> #REF! | AJ650: =IF(InputOutput!#REF!="","",InputOutput!#REF!) -> #REF! | AK650: =IF(InputOutput!#REF!="","",InputOutput!#REF!) -> #REF! | AL650: =IF(InputOutput!#REF!="","",InputOutput!#REF!) -> #REF! | AM650: =IF(InputOutput!#REF!="","",InputOutput!#REF!) -> #REF! | AN650: =IF(InputOutput!#REF!="","",InputOutput!#REF!) -> #REF!
A651: =IF(InputOutput!#REF!="","",InputOutput!#REF!) -> #REF! | B651: =IF(InputOutput!#REF!="","",InputOutput!#REF!) -> #REF! | C651: =IF(InputOutput!#REF!="","",InputOutput!#REF!) -> #REF! | D651: =IF(InputOutput!#REF!="","",InputOutput!#REF!) -> #REF! | E651: =IF(InputOutput!#REF!="","",InputOutput!#REF!) -> #REF! | F651: =IF(InputOutput!#REF!="","",InputOutput!#REF!) -> #REF! | G651: =IF(InputOutput!#REF!="","",InputOutput!#REF!) -> #REF! | H651: =IF(InputOutput!#REF!="","",InputOutput!#REF!) -> #REF! | ... AD651: =IF(InputOutput!#REF!="","",InputOutput!#REF!) -> #REF! | AE651: =IF(InputOutput!#REF!="","",ROUND(InputOutput!#REF!,0)) -> #REF! | AF651: =IF(InputOutput!#REF!="","",ROUND(InputOutput!#REF!,0)) -> #REF! | AG651: =IF(InputOutput!#REF!="","",InputOutput!#REF!) -> #REF! | AH651: =IF(InputOutput!#REF!="","",InputOutput!#REF!) -> #REF! | AI651: =IF(InputOutput!#REF!="","",InputOutput!#REF!) -> #REF! | AJ651: =IF(InputOutput!#REF!="","",InputOutput!#REF!) -> #REF! | AK651: =IF(InputOutput!#REF!="","",InputOutput!#REF!) -> #REF! | AL651: =IF(InputOutput!#REF!="","",InputOutput!#REF!) -> #REF! | AM651: =IF(InputOutput!#REF!="","",InputOutput!#REF!) -> #REF! | AN651: =IF(InputOutput!#REF!="","",InputOutput!#REF!) -> #REF!
A652: =IF(InputOutput!#REF!="","",InputOutput!#REF!) -> #REF! | B652: =IF(InputOutput!#REF!="","",InputOutput!#REF!) -> #REF! | C652: =IF(InputOutput!#REF!="","",InputOutput!#REF!) -> #REF! | D652: =IF(InputOutput!#REF!="","",InputOutput!#REF!) -> #REF! | E652: =IF(InputOutput!#REF!="","",InputOutput!#REF!) -> #REF! | F652: =IF(InputOutput!#REF!="","",InputOutput!#REF!) -> #REF! | G652: =IF(InputOutput!#REF!="","",InputOutput!#REF!) -> #REF! | H652: =IF(InputOutput!#REF!="","",InputOutput!#REF!) -> #REF! | ... AD652: =IF(InputOutput!#REF!="","",InputOutput!#REF!) -> #REF! | AE652: =IF(InputOutput!#REF!="","",ROUND(InputOutput!#REF!,0)) -> #REF! | AF652: =IF(InputOutput!#REF!="","",ROUND(InputOutput!#REF!,0)) -> #REF! | AG652: =IF(InputOutput!#REF!="","",InputOutput!#REF!) -> #REF! | AH652: =IF(InputOutput!#REF!="","",InputOutput!#REF!) -> #REF! | AI652: =IF(InputOutput!#REF!="","",InputOutput!#REF!) -> #REF! | AJ652: =IF(InputOutput!#REF!="","",InputOutput!#REF!) -> #REF! | AK652: =IF(InputOutput!#REF!="","",InputOutput!#REF!) -> #REF! | AL652: =IF(InputOutput!#REF!="","",InputOutput!#REF!) -> #REF! | AM652: =IF(InputOutput!#REF!="","",InputOutput!#REF!) -> #REF! | AN652: =IF(InputOutput!#REF!="","",InputOutput!#REF!) -> #REF!
A653: =IF(InputOutput!#REF!="","",InputOutput!#REF!) -> #REF! | B653: =IF(InputOutput!#REF!="","",InputOutput!#REF!) -> #REF! | C653: =IF(InputOutput!#REF!="","",InputOutput!#REF!) -> #REF! | D653: =IF(InputOutput!#REF!="","",InputOutput!#REF!) -> #REF! | E653: =IF(InputOutput!#REF!="","",InputOutput!#REF!) -> #REF! | F653: =IF(InputOutput!#REF!="","",InputOutput!#REF!) -> #REF! | G653: =IF(InputOutput!#REF!="","",InputOutput!#REF!) -> #REF! | H653: =IF(InputOutput!#REF!="","",InputOutput!#REF!) -> #REF! | ... AD653: =IF(InputOutput!#REF!="","",InputOutput!#REF!) -> #REF! | AE653: =IF(InputOutput!#REF!="","",ROUND(InputOutput!#REF!,0)) -> #REF! | AF653: =IF(InputOutput!#REF!="","",ROUND(InputOutput!#REF!,0)) -> #REF! | AG653: =IF(InputOutput!#REF!="","",InputOutput!#REF!) -> #REF! | AH653: =IF(InputOutput!#REF!="","",InputOutput!#REF!) -> #REF! | AI653: =IF(InputOutput!#REF!="","",InputOutput!#REF!) -> #REF! | AJ653: =IF(InputOutput!#REF!="","",InputOutput!#REF!) -> #REF! | AK653: =IF(InputOutput!#REF!="","",InputOutput!#REF!) -> #REF! | AL653: =IF(InputOutput!#REF!="","",InputOutput!#REF!) -> #REF! | AM653: =IF(InputOutput!#REF!="","",InputOutput!#REF!) -> #REF! | AN653: =IF(InputOutput!#REF!="","",InputOutput!#REF!) -> #REF!
A654: =IF(InputOutput!#REF!="","",InputOutput!#REF!) -> #REF! | B654: =IF(InputOutput!#REF!="","",InputOutput!#REF!) -> #REF! | C654: =IF(InputOutput!#REF!="","",InputOutput!#REF!) -> #REF! | D654: =IF(InputOutput!#REF!="","",InputOutput!#REF!) -> #REF! | E654: =IF(InputOutput!#REF!="","",InputOutput!#REF!) -> #REF! | F654: =IF(InputOutput!#REF!="","",InputOutput!#REF!) -> #REF! | G654: =IF(InputOutput!#REF!="","",InputOutput!#REF!) -> #REF! | H654: =IF(InputOutput!#REF!="","",InputOutput!#REF!) -> #REF! | ... AD654: =IF(InputOutput!#REF!="","",InputOutput!#REF!) -> #REF! | AE654: =IF(InputOutput!#REF!="","",ROUND(InputOutput!#REF!,0)) -> #REF! | AF654: =IF(InputOutput!#REF!="","",ROUND(InputOutput!#REF!,0)) -> #REF! | AG654: =IF(InputOutput!#REF!="","",InputOutput!#REF!) -> #REF! | AH654: =IF(InputOutput!#REF!="","",InputOutput!#REF!) -> #REF! | AI654: =IF(InputOutput!#REF!="","",InputOutput!#REF!) -> #REF! | AJ654: =IF(InputOutput!#REF!="","",InputOutput!#REF!) -> #REF! | AK654: =IF(InputOutput!#REF!="","",InputOutput!#REF!) -> #REF! | AL654: =IF(InputOutput!#REF!="","",InputOutput!#REF!) -> #REF! | AM654: =IF(InputOutput!#REF!="","",InputOutput!#REF!) -> #REF! | AN654: =IF(InputOutput!#REF!="","",InputOutput!#REF!) -> #REF!
