Workbook

Sheet linear
A1: Copy to Clipboard
A2: Interaction diagram - Axial force resistance NRd vs bending moment resistance MRd
A3: N-M interaction | B3: Lever arm & neutral axis | C3: Curvature & strains | D3: Stresses | E3: Internal forces & moments | F3: Effective stiffness
A4: # | B4: Design axial force resistance
A5: NRd [kN] | B5: Design bending moment resistance
A6: MRd [kNm] | B6: Location of neutral axis from centroid
A7: yn [m] | B7: Lever arm of internal forces
A8: z [m] | B8: Normalized level arm
A9: z/d [-] | B9: Depth of compressive zone
A10: x [m] | B10: Normalized depth of compressive zone
A11: x/d [-] | B11: Area of compressive zone
A12: AC [m2] | B12: Curvature
A13: φ [×10−3 m−1] | B13: Strain at centroid
A14: ε0 [‰] | B14: Top concrete strain
A15: εc,top [‰] | B15: Bottom concrete strain
... A17: εs,max [‰] | B17: Minimum reinforcement strain
A18: εs,min [‰] | B18: Reinforcement yield in tension | C18: Reinforcement yield in compression | D18: Maximum concrete stress
A19: σc,max [MPa] | B19: Minimum concrete stress
A20: σc,min [MPa] | B20: Average concrete stress
A21: σc,ave [MPa] | B21: Maximum reinforcement stress
A22: σs,max [MPa] | B22: Minimum reinforcement stress
A23: σs,min [MPa] | B23: Internal compression force
A24: FC [kN] | B24: Internal tension force
A25: FT [kN] | B25: Internal compression moment
A26: MC [kNm] | B26: Internal tension moment
A27: MT [kNm] | B27: Effective bending stiffness
A28: (EI)eff [kNm2] | B28: Effective bending stiffness ratio
A29: (EI)eff / (EI)gross [-]
A30: 1 | B30: 376.99 | C30: 0 | D30: Infinity | E30: - | F30: - | G30: 0 | H30: 0 | I30: 0 | J30: 0 | K30: 1.5 | L30: 1.5 | M30: 1.5 | N30: 1.5 | O30: 1.5 | P30: no | Q30: no | R30: 0 | S30: 0 | T30: 0 | U30: 300 | V30: 300 | W30: 0 | X30: 376.99 | Y30: 0 | Z30: 0 | AA30: NaN | AB30: NaN
A31: 2 | B31: 368.4 | C31: 0.6 | D31: 3 | E31: - | F31: - | G31: 0 | H31: 0 | I31: 0 | J31: 0.489 | K31: 1.47 | L31: 1.4 | M31: 1.53 | N31: 1.5 | O31: 1.43 | P31: no | Q31: no | R31: 0 | S31: 0 | T31: 0 | U31: 300 | V31: 286.3 | W31: 0 | X31: 368.4 | Y31: 0 | Z31: 0.6 | AA31: 1232 | AB31: 0.0746
A32: 3 | B32: 359.8 | C32: 1.2 | D32: 1.465 | E32: - | F32: - | G32: 0 | H32: 0 | I32: 0 | J32: 0.977 | K32: 1.43 | L32: 1.3 | M32: 1.56 | N32: 1.5 | O32: 1.36 | P32: no | Q32: no | R32: 0 | S32: 0 | T32: 0 | U32: 300 | V32: 272.6 | W32: 0 | X32: 359.8 | Y32: 0 | Z32: 1.2 | AA32: 1232 | AB32: 0.0746
A33: 4 | B33: 351.21 | C33: 1.8 | D33: 0.953 | E33: - | F33: - | G33: 0 | H33: 0 | I33: 0 | J33: 1.466 | K33: 1.4 | L33: 1.2 | M33: 1.6 | N33: 1.5 | O33: 1.29 | P33: no | Q33: no | R33: 0 | S33: 0 | T33: 0 | U33: 300 | V33: 259 | W33: 0 | X33: 351.21 | Y33: 0 | Z33: 1.8 | AA33: 1232 | AB33: 0.0746
A34: 5 | B34: 342.61 | C34: 2.41 | D34: 0.698 | E34: - | F34: - | G34: 0 | H34: 0 | I34: 0 | J34: 1.954 | K34: 1.36 | L34: 1.1 | M34: 1.63 | N34: 1.5 | O34: 1.23 | P34: no | Q34: no | R34: 0 | S34: 0 | T34: 0 | U34: 300 | V34: 245.3 | W34: 0 | X34: 342.61 | Y34: 0 | Z34: 2.41 | AA34: 1232 | AB34: 0.0746
A35: 6 | B35: 334.02 | C35: 3.01 | D35: 0.544 | E35: - | F35: - | G35: 0 | H35: 0 | I35: 0 | J35: 2.443 | K35: 1.33 | L35: 1 | M35: 1.66 | N35: 1.5 | O35: 1.16 | P35: no | Q35: no | R35: 0 | S35: 0 | T35: 0 | U35: 300 | V35: 231.6 | W35: 0 | X35: 334.02 | Y35: 0 | Z35: 3.01 | AA35: 1232 | AB35: 0.0746
A36: 7 | B36: 325.42 | C36: 3.61 | D36: 0.442 | E36: - | F36: - | G36: 0 | H36: 0 | I36: 0 | J36: 2.931 | K36: 1.29 | L36: 0.9 | M36: 1.69 | N36: 1.5 | O36: 1.09 | P36: no | Q36: no | R36: 0 | S36: 0 | T36: 0 | U36: 300 | V36: 217.9 | W36: 0 | X36: 325.42 | Y36: 0 | Z36: 3.61 | AA36: 1232 | AB36: 0.0746
A37: 8 | B37: 316.83 | C37: 4.21 | D37: 0.369 | E37: - | F37: - | G37: 0 | H37: 0 | I37: 0 | J37: 3.42 | K37: 1.26 | L37: 0.8 | M37: 1.72 | N37: 1.5 | O37: 1.02 | P37: no | Q37: no | R37: 0 | S37: 0 | T37: 0 | U37: 300 | V37: 204.2 | W37: 0 | X37: 316.83 | Y37: 0 | Z37: 4.21 | AA37: 1232 | AB37: 0.0746
A38: 9 | B38: 308.23 | C38: 4.81 | D38: 0.314 | E38: - | F38: - | G38: 0 | H38: 0 | I38: 0 | J38: 3.908 | K38: 1.23 | L38: 0.7 | M38: 1.75 | N38: 1.5 | O38: 0.95 | P38: no | Q38: no | R38: 0 | S38: 0 | T38: 0 | U38: 300 | V38: 190.6 | W38: 0 | X38: 308.23 | Y38: 0 | Z38: 4.81 | AA38: 1232 | AB38: 0.0746
A39: 10 | B39: 299.64 | C39: 5.41 | D39: 0.271 | E39: - | F39: - | G39: 0 | H39: 0 | I39: 0 | J39: 4.397 | K39: 1.19 | L39: 0.6 | M39: 1.79 | N39: 1.5 | O39: 0.88 | P39: no | Q39: no | R39: 0 | S39: 0 | T39: 0 | U39: 300 | V39: 176.9 | W39: 0 | X39: 299.64 | Y39: 0 | Z39: 5.41 | AA39: 1232 | AB39: 0.0746
A40: 11 | B40: 291.04 | C40: 6.02 | D40: 0.237 | E40: - | F40: - | G40: 0 | H40: 0 | I40: 0 | J40: 4.885 | K40: 1.16 | L40: 0.5 | M40: 1.82 | N40: 1.5 | O40: 0.82 | P40: no | Q40: no | R40: 0 | S40: 0 | T40: 0 | U40: 300 | V40: 163.2 | W40: 0 | X40: 291.04 | Y40: 0 | Z40: 6.02 | AA40: 1232 | AB40: 0.0746
A41: 12 | B41: 282.45 | C41: 6.62 | D41: 0.209 | E41: - | F41: - | G41: 0 | H41: 0 | I41: 0 | J41: 5.374 | K41: 1.12 | L41: 0.4 | M41: 1.85 | N41: 1.5 | O41: 0.75 | P41: no | Q41: no | R41: 0 | S41: 0 | T41: 0 | U41: 300 | V41: 149.5 | W41: 0 | X41: 282.45 | Y41: 0 | Z41: 6.62 | AA41: 1232 | AB41: 0.0746
...

Sheet parabolic
A1: Copy to Clipboard
A2: Interaction diagram - Axial force resistance NRd vs bending moment resistance MRd
A3: N-M interaction | B3: Lever arm & neutral axis | C3: Curvature & strains | D3: Stresses | E3: Internal forces & moments | F3: Effective stiffness
A4: # | B4: Design axial force resistance
A5: NRd [kN] | B5: Design bending moment resistance
A6: MRd [kNm] | B6: Location of neutral axis from centroid
A7: yn [m] | B7: Lever arm of internal forces
A8: z [m] | B8: Normalized level arm
A9: z/d [-] | B9: Depth of compressive zone
A10: x [m] | B10: Normalized depth of compressive zone
A11: x/d [-] | B11: Area of compressive zone
A12: AC [m2] | B12: Curvature
A13: φ [×10−3 m−1] | B13: Strain at centroid
A14: ε0 [‰] | B14: Top concrete strain
A15: εc,top [‰] | B15: Bottom concrete strain
... A17: εs,max [‰] | B17: Minimum reinforcement strain
A18: εs,min [‰] | B18: Reinforcement yield in tension | C18: Reinforcement yield in compression | D18: Maximum concrete stress
A19: σc,max [MPa] | B19: Minimum concrete stress
A20: σc,min [MPa] | B20: Average concrete stress
A21: σc,ave [MPa] | B21: Maximum reinforcement stress
A22: σs,max [MPa] | B22: Minimum reinforcement stress
A23: σs,min [MPa] | B23: Internal compression force
A24: FC [kN] | B24: Internal tension force
A25: FT [kN] | B25: Internal compression moment
A26: MC [kNm] | B26: Internal tension moment
A27: MT [kNm] | B27: Effective bending stiffness
A28: (EI)eff [kNm2] | B28: Effective bending stiffness ratio
A29: (EI)eff / (EI)gross [-]
A30: 1 | B30: 502.65 | C30: 0 | D30: Infinity | E30: - | F30: - | G30: 0 | H30: 0 | I30: 0 | J30: 0 | K30: 2 | L30: 2 | M30: 2 | N30: 2 | O30: 2 | P30: no | Q30: no | R30: 0 | S30: 0 | T30: 0 | U30: 400 | V30: 400 | W30: 0 | X30: 502.65 | Y30: 0 | Z30: 0 | AA30: NaN | AB30: NaN
A31: 2 | B31: 490.92 | C31: 0.82 | D31: 2.928 | E31: - | F31: - | G31: 0 | H31: 0 | I31: 0 | J31: 0.667 | K31: 1.95 | L31: 1.86 | M31: 2.04 | N31: 2 | O31: 1.91 | P31: no | Q31: no | R31: 0 | S31: 0 | T31: 0 | U31: 400 | V31: 381.3 | W31: 0 | X31: 490.92 | Y31: 0 | Z31: 0.82 | AA31: 1232 | AB31: 0.0746
A32: 3 | B32: 479.18 | C32: 1.64 | D32: 1.429 | E32: - | F32: - | G32: 0 | H32: 0 | I32: 0 | J32: 1.334 | K32: 1.91 | L32: 1.73 | M32: 2.09 | N32: 2 | O32: 1.81 | P32: no | Q32: no | R32: 0 | S32: 0 | T32: 0 | U32: 400 | V32: 362.6 | W32: 0 | X32: 479.18 | Y32: 0 | Z32: 1.64 | AA32: 1232 | AB32: 0.0746
A33: 4 | B33: 467.45 | C33: 2.46 | D33: 0.929 | E33: - | F33: - | G33: 0 | H33: 0 | I33: 0 | J33: 2.001 | K33: 1.86 | L33: 1.59 | M33: 2.13 | N33: 2 | O33: 1.72 | P33: no | Q33: no | R33: 0 | S33: 0 | T33: 0 | U33: 400 | V33: 344 | W33: 0 | X33: 467.45 | Y33: 0 | Z33: 2.46 | AA33: 1232 | AB33: 0.0746
A34: 5 | B34: 455.71 | C34: 3.29 | D34: 0.68 | E34: - | F34: - | G34: 0 | H34: 0 | I34: 0 | J34: 2.668 | K34: 1.81 | L34: 1.45 | M34: 2.17 | N34: 2 | O34: 1.63 | P34: no | Q34: no | R34: 0 | S34: 0 | T34: 0 | U34: 400 | V34: 325.3 | W34: 0 | X34: 455.71 | Y34: 0 | Z34: 3.29 | AA34: 1232 | AB34: 0.0746
A35: 6 | B35: 443.97 | C35: 4.11 | D35: 0.53 | E35: - | F35: - | G35: 0 | H35: 0 | I35: 0 | J35: 3.335 | K35: 1.77 | L35: 1.32 | M35: 2.22 | N35: 2 | O35: 1.53 | P35: no | Q35: no | R35: 0 | S35: 0 | T35: 0 | U35: 400 | V35: 306.6 | W35: 0 | X35: 443.97 | Y35: 0 | Z35: 4.11 | AA35: 1232 | AB35: 0.0746
A36: 7 | B36: 432.24 | C36: 4.93 | D36: 0.43 | E36: - | F36: - | G36: 0 | H36: 0 | I36: 0 | J36: 4.003 | K36: 1.72 | L36: 1.18 | M36: 2.26 | N36: 2 | O36: 1.44 | P36: no | Q36: no | R36: 0 | S36: 0 | T36: 0 | U36: 400 | V36: 287.9 | W36: 0 | X36: 432.24 | Y36: 0 | Z36: 4.93 | AA36: 1232 | AB36: 0.0746
A37: 8 | B37: 420.5 | C37: 5.75 | D37: 0.358 | E37: - | F37: - | G37: 0 | H37: 0 | I37: 0 | J37: 4.67 | K37: 1.67 | L37: 1.04 | M37: 2.3 | N37: 2 | O37: 1.35 | P37: no | Q37: no | R37: 0 | S37: 0 | T37: 0 | U37: 400 | V37: 269.2 | W37: 0 | X37: 420.5 | Y37: 0 | Z37: 5.75 | AA37: 1232 | AB37: 0.0746
A38: 9 | B38: 408.77 | C38: 6.57 | D38: 0.305 | E38: - | F38: - | G38: 0 | H38: 0 | I38: 0 | J38: 5.337 | K38: 1.63 | L38: 0.91 | M38: 2.35 | N38: 2 | O38: 1.25 | P38: no | Q38: no | R38: 0 | S38: 0 | T38: 0 | U38: 400 | V38: 250.6 | W38: 0 | X38: 408.77 | Y38: 0 | Z38: 6.57 | AA38: 1232 | AB38: 0.0746
A39: 10 | B39: 397.03 | C39: 7.39 | D39: 0.263 | E39: - | F39: - | G39: 0 | H39: 0 | I39: 0 | J39: 6.004 | K39: 1.58 | L39: 0.77 | M39: 2.39 | N39: 2 | O39: 1.16 | P39: no | Q39: no | R39: 0 | S39: 0 | T39: 0 | U39: 400 | V39: 231.9 | W39: 0 | X39: 397.03 | Y39: 0 | Z39: 7.39 | AA39: 1232 | AB39: 0.0746
A40: 11 | B40: 385.29 | C40: 8.22 | D40: 0.23 | E40: - | F40: - | G40: 0 | H40: 0 | I40: 0 | J40: 6.671 | K40: 1.53 | L40: 0.63 | M40: 2.43 | N40: 2 | O40: 1.07 | P40: no | Q40: no | R40: 0 | S40: 0 | T40: 0 | U40: 400 | V40: 213.2 | W40: 0 | X40: 385.29 | Y40: 0 | Z40: 8.22 | AA40: 1232 | AB40: 0.0746
A41: 12 | B41: 373.56 | C41: 9.04 | D41: 0.203 | E41: - | F41: - | G41: 0 | H41: 0 | I41: 0 | J41: 7.338 | K41: 1.49 | L41: 0.5 | M41: 2.48 | N41: 2 | O41: 0.97 | P41: no | Q41: no | R41: 0 | S41: 0 | T41: 0 | U41: 400 | V41: 194.5 | W41: 0 | X41: 373.56 | Y41: 0 | Z41: 9.04 | AA41: 1232 | AB41: 0.0746
...

Sheet Sheet2
A1: Lineear | E1: Parabolic | J1: Centrum no crack | P1: Centrum 0.4 crack
A2: =linear!B30 -> 376.99 | B2: =linear!C30 -> 0 | C2: =A2*-1 -> -376.99 | E2: =parabolic!B30 -> 502.65 | F2: =parabolic!C30 -> 0 | G2: =E2*-1 -> -502.65 | J2: 1 | K2: 628.32 | L2: 0 | M2: =K2*-1 -> -628.32 | P2: -2616.7215 | Q2: 0.0014720624 | R2: =P2*-1 -> 2616.7215
A3: =linear!B31 -> 368.4 | B3: =linear!C31 -> 0.6 | C3: =A3*-1 -> -368.4 | E3: =parabolic!B31 -> 490.92 | F3: =parabolic!C31 -> 0.82 | G3: =E3*-1 -> -490.92 | J3: 2 | K3: 608.38 | L3: 1.4 | M3: =K3*-1 -> -608.38 | P3: -2547.6806 | Q3: 2.9438303 | R3: =P3*-1 -> 2547.6806
A4: =linear!B32 -> 359.8 | B4: =linear!C32 -> 1.2 | C4: =A4*-1 -> -359.8 | E4: =parabolic!B32 -> 479.18 | F4: =parabolic!C32 -> 1.64 | G4: =E4*-1 -> -479.18 | J4: 3 | K4: 588.44 | L4: 2.79 | M4: =K4*-1 -> -588.44 | P4: -2478.6189 | Q4: 5.887072 | R4: =P4*-1 -> 2478.6189
A5: =linear!B33 -> 351.21 | B5: =linear!C33 -> 1.8 | C5: =A5*-1 -> -351.21 | E5: =parabolic!B33 -> 467.45 | F5: =parabolic!C33 -> 2.46 | G5: =E5*-1 -> -467.45 | J5: 4 | K5: 568.5 | L5: 4.19 | M5: =K5*-1 -> -568.5 | P5: -2444.0933 | Q5: 7.3584722 | R5: =P5*-1 -> 2444.0933
A6: =linear!B34 -> 342.61 | B6: =linear!C34 -> 2.41 | C6: =A6*-1 -> -342.61 | E6: =parabolic!B34 -> 455.71 | F6: =parabolic!C34 -> 3.29 | G6: =E6*-1 -> -455.71 | J6: 5 | K6: 548.56 | L6: 5.58 | M6: =K6*-1 -> -548.56 | P6: -2424.9139 | Q6: 8.1758532 | R6: =P6*-1 -> 2424.9139 | U6: mn | V6: n
A7: =linear!B35 -> 334.02 | B7: =linear!C35 -> 3.01 | C7: =A7*-1 -> -334.02 | E7: =parabolic!B35 -> 443.97 | F7: =parabolic!C35 -> 4.11 | G7: =E7*-1 -> -443.97 | J7: 6 | K7: 528.62 | L7: 6.98 | M7: =K7*-1 -> -528.62 | P7: -2400.9411 | Q7: 9.1975155 | R7: =P7*-1 -> 2400.9411 | U7: -300 | V7: 25.88
A8: =linear!B36 -> 325.42 | B8: =linear!C36 -> 3.61 | C8: =A8*-1 -> -325.42 | E8: =parabolic!B36 -> 432.24 | F8: =parabolic!C36 -> 4.93 | G8: =E8*-1 -> -432.24 | J8: 7 | K8: 508.68 | L8: 8.37 | M8: =K8*-1 -> -508.68 | P8: -2370.1214 | Q8: 10.510977 | R8: =P8*-1 -> 2370.1214
A9: =linear!B37 -> 316.83 | B9: =linear!C37 -> 4.21 | C9: =A9*-1 -> -316.83 | E9: =parabolic!B37 -> 420.5 | F9: =parabolic!C37 -> 5.75 | G9: =E9*-1 -> -420.5 | J9: 8 | K9: 488.74 | L9: 9.77 | M9: =K9*-1 -> -488.74 | P9: -2351.1568 | Q9: 11.319203 | R9: =P9*-1 -> 2351.1568
A10: =linear!B38 -> 308.23 | B10: =linear!C38 -> 4.81 | C10: =A10*-1 -> -308.23 | E10: =parabolic!B38 -> 408.77 | F10: =parabolic!C38 -> 6.57 | G10: =E10*-1 -> -408.77 | J10: 9 | K10: 468.8 | L10: 11.17 | M10: =K10*-1 -> -468.8 | P10: -2329.0328 | Q10: 12.262077 | R10: =P10*-1 -> 2329.0328
A11: =linear!B39 -> 299.64 | B11: =linear!C39 -> 5.41 | C11: =A11*-1 -> -299.64 | E11: =parabolic!B39 -> 397.03 | F11: =parabolic!C39 -> 7.39 | G11: =E11*-1 -> -397.03 | J11: 10 | K11: 448.86 | L11: 12.56 | M11: =K11*-1 -> -448.86 | P11: -2302.888 | Q11: 13.376305 | R11: =P11*-1 -> 2302.888
A12: =linear!B40 -> 291.04 | B12: =linear!C40 -> 6.02 | C12: =A12*-1 -> -291.04 | E12: =parabolic!B40 -> 385.29 | F12: =parabolic!C40 -> 8.22 | G12: =E12*-1 -> -385.29 | J12: 11 | K12: 428.92 | L12: 13.96 | M12: =K12*-1 -> -428.92 | P12: -2271.5169 | Q12: 14.713267 | R12: =P12*-1 -> 2271.5169
A13: =linear!B41 -> 282.45 | B13: =linear!C41 -> 6.62 | C13: =A13*-1 -> -282.45 | E13: =parabolic!B41 -> 373.56 | F13: =parabolic!C41 -> 9.04 | G13: =E13*-1 -> -373.56 | J13: 12 | K13: 408.9 | L13: 15.36 | M13: =K13*-1 -> -408.9 | P13: -2253.3559 | Q13: 15.487242 | R13: =P13*-1 -> 2253.3559
A14: =linear!B42 -> 273.85 | B14: =linear!C42 -> 7.22 | C14: =A14*-1 -> -273.85 | E14: =parabolic!B42 -> 361.82 | F14: =parabolic!C42 -> 9.86 | G14: =E14*-1 -> -361.82 | J14: 13 | K14: 380.01 | L14: 17.89 | M14: =K14*-1 -> -380.01 | P14: -2233.1783 | Q14: 16.347167 | R14: =P14*-1 -> 2233.1783
A15: =linear!B43 -> 265.26 | B15: =linear!C43 -> 7.82 | C15: =A15*-1 -> -265.26 | E15: =parabolic!B43 -> 350.08 | F15: =parabolic!C43 -> 10.68 | G15: =E15*-1 -> -350.08 | J15: 14 | K15: 338.91 | L15: 21.82 | M15: =K15*-1 -> -338.91 | P15: -2210.6281 | Q15: 17.308199 | R15: =P15*-1 -> 2210.6281
A16: =linear!B44 -> 256.67 | B16: =linear!C44 -> 8.42 | C16: =A16*-1 -> -256.67 | E16: =parabolic!B44 -> 338.35 | F16: =parabolic!C44 -> 11.5 | G16: =E16*-1 -> -338.35 | J16: 15 | K16: 288.2 | L16: 26.7 | M16: =K16*-1 -> -288.2 | P16: -2185.261 | Q16: 18.389286 | R16: =P16*-1 -> 2185.261
A17: =linear!B45 -> 248.07 | B17: =linear!C45 -> 9.02 | C17: =A17*-1 -> -248.07 | E17: =parabolic!B45 -> 324.86 | F17: =parabolic!C45 -> 12.56 | G17: =E17*-1 -> -324.86 | J17: 16 | K17: 229.81 | L17: 32.27 | M17: =K17*-1 -> -229.81 | P17: -2156.5138 | Q17: 19.614422 | R17: =P17*-1 -> 2156.5138
A18: =linear!B46 -> 228.69 | B18: =linear!C46 -> 11.04 | C18: =A18*-1 -> -228.69 | E18: =parabolic!B46 -> 293.21 | F18: =parabolic!C46 -> 15.94 | G18: =E18*-1 -> -293.21 | J18: 17 | K18: 165.18 | L18: 38.32 | M18: =K18*-1 -> -165.18 | P18: -2123.6628 | Q18: 21.014452 | R18: =P18*-1 -> 2123.6628
A19: =linear!B47 -> 191.11 | B19: =linear!C47 -> 15.27 | C19: =A19*-1 -> -191.11 | E19: =parabolic!B47 -> 243.74 | F19: =parabolic!C47 -> 21.41 | G19: =E19*-1 -> -243.74 | J19: 18 | K19: 95.41 | L19: 44.72 | M19: =K19*-1 -> -95.41 | P19: -2085.7617 | Q19: 22.629706 | R19: =P19*-1 -> 2085.7617
... A142: =linear!B170 -> -2313.41 | B142: =linear!C170 -> 0 | C142: =A142*-1 -> 2313.41 | E142: =parabolic!B170 -> -2371.75 | F142: =parabolic!C170 -> 0 | G142: =E142*-1 -> 2371.75 | J142: 141 | K142: -2632.1 | L142: 0 | M142: =K142*-1 -> 2632.1 | P142: -16.513085 | Q142: 42.773436 | R142: =P142*-1 -> 16.513085
P143: -7.1601988 | Q143: 41.889661 | R143: =P143*-1 -> 7.1601988
P144: 1.949107 | Q144: 41.02528 | R144: =P144*-1 -> -1.949107
P145: 10.821335 | Q145: 40.179848 | R145: =P145*-1 -> -10.821335
P146: 19.46277 | Q146: 39.352935 | R146: =P146*-1 -> -19.46277
P147: 27.87949 | Q147: 38.544124 | R147: =P147*-1 -> -27.87949
P148: 36.077371 | Q148: 37.753012 | R148: =P148*-1 -> -36.077371
P149: 44.062101 | Q149: 36.979209 | R149: =P149*-1 -> -44.062101
P150: 51.83918 | Q150: 36.222335 | R150: =P150*-1 -> -51.83918
P151: 59.413933 | Q151: 35.482024 | R151: =P151*-1 -> -59.413933
P152: 66.791515 | Q152: 34.757921 | R152: =P152*-1 -> -66.791515
P153: 73.976918 | Q153: 34.049681 | R153: =P153*-1 -> -73.976918
P154: 80.974976 | Q154: 33.356972 | R154: =P154*-1 -> -80.974976
... P201: 317.48789 | Q201: 0.0015554853 | R201: =P201*-1 -> -317.48789

Sheet Sheet1

Sheet Sheet3
A1: Copy to Clipboard
A2: Interaction diagram - Axial force resistance NRd vs bending moment resistance MRd
A3: N-M interaction | B3: Lever arm & neutral axis | C3: Curvature & strains | D3: Stresses | E3: Internal forces & moments | F3: Effective stiffness
A4: # | B4: Design axial force resistance
A5: NRd [kN] | B5: Design bending moment resistance
A6: MRd [kNm] | B6: Location of neutral axis from centroid
A7: yn [m] | B7: Lever arm of internal forces
A8: z [m] | B8: Normalized level arm
A9: z/d [-] | B9: Depth of compressive zone
A10: x [m] | B10: Normalized depth of compressive zone
A11: x/d [-] | B11: Area of compressive zone
A12: AC [m2] | B12: Curvature
A13: φ [×10−3 m−1] | B13: Strain at centroid
A14: ε0 [‰] | B14: Top concrete strain
A15: εc,top [‰] | B15: Bottom concrete strain
... A17: εs,max [‰] | B17: Minimum reinforcement strain
A18: εs,min [‰] | B18: Reinforcement yield in tension | C18: Reinforcement yield in compression | D18: Maximum concrete stress
A19: σc,max [MPa] | B19: Minimum concrete stress
A20: σc,min [MPa] | B20: Average concrete stress
A21: σc,ave [MPa] | B21: Maximum reinforcement stress
A22: σs,max [MPa] | B22: Minimum reinforcement stress
A23: σs,min [MPa] | B23: Internal compression force
A24: FC [kN] | B24: Internal tension force
A25: FT [kN] | B25: Internal compression moment
A26: MC [kNm] | B26: Internal tension moment
A27: MT [kNm] | B27: Effective bending stiffness
A28: (EI)eff [kNm2] | B28: Effective bending stiffness ratio
A29: (EI)eff / (EI)gross [-]
A30: 1 | B30: 628.32 | C30: 0 | D30: Infinity | E30: - | F30: - | G30: 0 | H30: 0 | I30: 0 | J30: 0 | K30: 2.5 | L30: 2.5 | M30: 2.5 | N30: 2.5 | O30: 2.5 | P30: yes | Q30: no | R30: 0 | S30: 0 | T30: 0 | U30: 500 | V30: 500 | W30: 0 | X30: 628.32 | Y30: 0 | Z30: 0 | AA30: NaN | AB30: NaN | AF30: =B30*-1 -> -628.32 | AG30: =C30 -> 0
A31: 2 | B31: 608.62 | C31: 1.38 | D31: 2.163 | E31: - | F31: - | G31: 0 | H31: 0 | I31: 0 | J31: 1.12 | K31: 2.42 | L31: 2.27 | M31: 2.57 | N31: 2.5 | O31: 2.34 | P31: yes | Q31: no | R31: 0 | S31: 0 | T31: 0 | U31: 500 | V31: 468.7 | W31: 0 | X31: 608.62 | Y31: 0 | Z31: 1.38 | AA31: 1232 | AB31: 0.0746 | AF31: =B31*-1 -> -608.62 | AG31: =C31 -> 1.38
A32: 3 | B32: 588.92 | C32: 2.76 | D32: 1.046 | E32: - | F32: - | G32: 0 | H32: 0 | I32: 0 | J32: 2.239 | K32: 2.34 | L32: 2.04 | M32: 2.65 | N32: 2.5 | O32: 2.19 | P32: yes | Q32: no | R32: 0 | S32: 0 | T32: 0 | U32: 500 | V32: 437.3 | W32: 0 | X32: 588.92 | Y32: 0 | Z32: 2.76 | AA32: 1232 | AB32: 0.0746 | AF32: =B32*-1 -> -588.92 | AG32: =C32 -> 2.76
A33: 4 | B33: 569.23 | C33: 4.14 | D33: 0.674 | E33: - | F33: - | G33: 0 | H33: 0 | I33: 0 | J33: 3.359 | K33: 2.26 | L33: 1.81 | M33: 2.72 | N33: 2.5 | O33: 2.03 | P33: yes | Q33: no | R33: 0 | S33: 0 | T33: 0 | U33: 500 | V33: 406 | W33: 0 | X33: 569.23 | Y33: 0 | Z33: 4.14 | AA33: 1232 | AB33: 0.0746 | AF33: =B33*-1 -> -569.23 | AG33: =C33 -> 4.14
A34: 5 | B34: 549.53 | C34: 5.52 | D34: 0.488 | E34: - | F34: - | G34: 0 | H34: 0 | I34: 0 | J34: 4.478 | K34: 2.19 | L34: 1.58 | M34: 2.79 | N34: 2.5 | O34: 1.87 | P34: yes | Q34: no | R34: 0 | S34: 0 | T34: 0 | U34: 500 | V34: 374.6 | W34: 0 | X34: 549.53 | Y34: 0 | Z34: 5.52 | AA34: 1232 | AB34: 0.0746 | AF34: =B34*-1 -> -549.53 | AG34: =C34 -> 5.52
A35: 6 | B35: 529.83 | C35: 6.89 | D35: 0.377 | E35: - | F35: - | G35: 0 | H35: 0 | I35: 0 | J35: 5.598 | K35: 2.11 | L35: 1.35 | M35: 2.86 | N35: 2.5 | O35: 1.72 | P35: yes | Q35: no | R35: 0 | S35: 0 | T35: 0 | U35: 500 | V35: 343.3 | W35: 0 | X35: 529.83 | Y35: 0 | Z35: 6.89 | AA35: 1232 | AB35: 0.0746 | AF35: =B35*-1 -> -529.83 | AG35: =C35 -> 6.89
A36: 7 | B36: 510.14 | C36: 8.27 | D36: 0.302 | E36: - | F36: - | G36: 0 | H36: 0 | I36: 0 | J36: 6.718 | K36: 2.03 | L36: 1.12 | M36: 2.94 | N36: 2.5 | O36: 1.56 | P36: yes | Q36: no | R36: 0 | S36: 0 | T36: 0 | U36: 500 | V36: 311.9 | W36: 0 | X36: 510.14 | Y36: 0 | Z36: 8.27 | AA36: 1232 | AB36: 0.0746 | AF36: =B36*-1 -> -510.14 | AG36: =C36 -> 8.27
A37: 8 | B37: 490.44 | C37: 9.65 | D37: 0.249 | E37: - | F37: - | G37: 0 | H37: 0 | I37: 0 | J37: 7.837 | K37: 1.95 | L37: 0.89 | M37: 3.01 | N37: 2.5 | O37: 1.4 | P37: yes | Q37: no | R37: 0 | S37: 0 | T37: 0 | U37: 500 | V37: 280.6 | W37: 0 | X37: 490.44 | Y37: 0 | Z37: 9.65 | AA37: 1232 | AB37: 0.0746 | AF37: =B37*-1 -> -490.44 | AG37: =C37 -> 9.65
A38: 9 | B38: 470.74 | C38: 11.03 | D38: 0.209 | E38: - | F38: - | G38: 0 | H38: 0 | I38: 0 | J38: 8.957 | K38: 1.87 | L38: 0.66 | M38: 3.08 | N38: 2.5 | O38: 1.25 | P38: yes | Q38: no | R38: 0 | S38: 0 | T38: 0 | U38: 500 | V38: 249.2 | W38: 0 | X38: 470.74 | Y38: 0 | Z38: 11.03 | AA38: 1232 | AB38: 0.0746 | AF38: =B38*-1 -> -470.74 | AG38: =C38 -> 11.03
A39: 10 | B39: 451.05 | C39: 12.41 | D39: 0.178 | E39: - | F39: - | G39: 0 | H39: 0 | I39: 0 | J39: 10.076 | K39: 1.79 | L39: 0.43 | M39: 3.15 | N39: 2.5 | O39: 1.09 | P39: yes | Q39: no | R39: 0 | S39: 0 | T39: 0 | U39: 500 | V39: 217.9 | W39: 0 | X39: 451.05 | Y39: 0 | Z39: 12.41 | AA39: 1232 | AB39: 0.0746 | AF39: =B39*-1 -> -451.05 | AG39: =C39 -> 12.41
A40: 11 | B40: 431.35 | C40: 13.79 | D40: 0.153 | E40: - | F40: - | G40: 0 | H40: 0 | I40: 0 | J40: 11.196 | K40: 1.72 | L40: 0.2 | M40: 3.23 | N40: 2.5 | O40: 0.93 | P40: yes | Q40: no | R40: 0 | S40: 0 | T40: 0 | U40: 500 | V40: 186.5 | W40: 0 | X40: 431.35 | Y40: 0 | Z40: 13.79 | AA40: 1232 | AB40: 0.0746 | AF40: =B40*-1 -> -431.35 | AG40: =C40 -> 13.79
A41: 12 | B41: 411.57 | C41: 15.18 | D41: 0.133 | E41: 0.171 | F41: 0.835 | G41: 0.002 | H41: 0.01 | I41: 0.0004 | J41: 12.315 | K41: 1.64 | L41: -0.02 | M41: 3.3 | N41: 2.5 | O41: 0.78 | P41: yes | Q41: no | R41: 0 | S41: -0.35 | T41: -0.23 | U41: 500 | V41: 155.2 | W41: -0.09 | X41: 411.65 | Y41: 0.01 | Z41: 15.17 | AA41: 1232 | AB41: 0.0747 | AF41: =B41*-1 -> -411.57 | AG41: =C41 -> 15.18
...

Sheet Centrum 
A1: Ei halkeamaa 270 | E1: 0.0014720624 | F1: -2616.7215
A2: myyt 1 | E2: 2.9438303 | F2: -2547.6806
E3: 5.887072 | F3: -2478.6189
E4: 7.3584722 | F4: -2444.0933
E5: 8.1758532 | F5: -2424.9139
E6: 9.1975155 | F6: -2400.9411
E7: 10.510977 | F7: -2370.1214
E8: 11.319203 | F8: -2351.1568
E9: 12.262077 | F9: -2329.0328
E10: 13.376305 | F10: -2302.888
E11: 14.713267 | F11: -2271.5169
E12: 15.487242 | F12: -2253.3559
E13: 16.347167 | F13: -2233.1783
E14: 17.308199 | F14: -2210.6281
... E200: 0.003078139 | F200: 628.27456

Sheet Sheet4
I3: h.top | J3: =G4/2 -> 135
F4: h | G4: 270 | I4: b.top | J4: =-G4/2 -> -135
F8: top | G8: 0.000592
F9: bottom | G9: -0.003454
E14: =J3 -> 135 | F14: =G8 -> 0.000592
E15: =J4 -> -135 | F15: =G9 -> -0.003454
